Workbook

Sheet OFICIAL
B1: MUNDIAL DE FÚTBOL QATAR 2022
A3: Partido | B3: Fecha | G3: Resultado
A5: Grupo A
A6: 1 | B6: 44885 | D6: Qatar | G6: 0 | H6: 2 | I6: Ecuador
A7: 3 | B7: 44886 | D7: Senegal | I7: Países Bajos
A8: 18 | B8: 44890 | D8: Qatar | I8: Senegal
A9: 19 | B9: 44890 | D9: Países Bajos | I9: Ecuador
A10: 33 | B10: 44894 | D10: Países Bajos | I10: Qatar
A11: 34 | B11: 44894 | D11: Ecuador | I11: Senegal
A12: Grupo B
A13: 2 | B13: 44886 | D13: Inglaterra | I13: Irán
A14: 4 | B14: 44886 | D14: USA | I14: Gales
A15: 17 | B15: 44890 | D15: Gales | I15: Irán
A16: 20 | B16: 44890 | D16: Inglaterra | I16: USA
A17: 35 | B17: 44894 | D17: Gales | I17: Inglaterra
A18: 36 | B18: 44894 | D18: Irán | I18: USA
A19: Grupo C
A20: 5 | B20: 44887 | D20: Argentina | I20: Arabia Saudí
A21: 7 | B21: 44887 | D21: México | I21: Polonia
A22: 22 | B22: 44891 | D22: Polonia | I22: Arabia Saudí
A23: 24 | B23: 44891 | D23: Argentina | I23: México
A24: 39 | B24: 44895 | D24: Arabia Saudí | I24: México
A25: 40 | B25: 44895 | D25: Polonia | I25: Argentina
A26: Grupo D
A27: 6 | B27: 44887 | D27: Dinamarca | I27: Túnez
A28: 8 | B28: 44887 | D28: Francia | I28: Australia
A29: 21 | B29: 44891 | D29: Túnez | I29: Australia
A30: 23 | B30: 44891 | D30: Francia | I30: Dinamarca
A31: 37 | B31: 44895 | D31: Túnez | I31: Francia
A32: 38 | B32: 44895 | D32: Australia | I32: Dinamarca
A33: Grupo E
A34: 10 | B34: 44888 | D34: Alemania | I34: Japón
A35: 11 | B35: 44888 | D35: España | I35: Costa Rica
A36: 25 | B36: 44892 | D36: Japón | I36: Costa Rica
A37: 28 | B37: 44892 | D37: España | I37: Alemania
A38: 43 | B38: 44896 | D38: Japón | I38: España
A39: 44 | B39: 44896 | D39: Costa Rica | I39: Alemania
A40: Grupo F
A41: 9 | B41: 44888 | D41: Marruecos | I41: Croacia
A42: 12 | B42: 44888 | D42: Bélgica | I42: Canadá
...

Sheet XXX
B1: MUNDIAL DE FÚTBOL QATAR 2022 | O1: Premios | Q1: 1 Puesto | S1: 0.7
B2: Escribir solo en las cajas | E2: VERDES | L2: 5 | M2: E | Q2: 2 Puesto | S2: 0.2
B3: No toque ni re formatee nada | Q3: 3 Puesto | S3: 0.1
B5: PARTICIPANTE: | L5: Resultado: 1 Pt | Q5: No tocar Columnas
L6: Exacto: 4 Pts | Q6: Naranjas
A8: Partido | B8: Fecha | G8: Resultado | L8: Resultado | Q8: Pts
G9: Suyo | L9: Real | Q9: Resu | R9: Exac | S9: Total
A10: Grupo A
A11: 1 | B11: 44885 | D11: Qatar | I11: Ecuador | L11: =OFICIAL!G6 -> 0 | M11: =OFICIAL!G6 -> 0 | N11: 0 | O11: =OFICIAL!I6 -> Ecuador | Q11: =IF(AND(OR(AND(G11-H11>0,L11-N11>0),AND(G11-H11<0,L11-N11<0),AND(G11-H11=0,L11-N11=0)),L11>-1,N11>-1),1,0) -> 1 | R11: =IF(AND(G11=L11,H11=N11,L11>-1,G11>-1),3,0) -> 3 | S11: =Q11+R11 -> 4
A12: 3 | B12: 44886 | D12: Senegal | I12: Países Bajos | L12: =OFICIAL!G7 -> 0 | M12: =OFICIAL!G7 -> 0 | N12: =OFICIAL!H7 -> 0 | O12: =OFICIAL!I7 -> Países Bajos | Q12: =IF(AND(OR(AND(G12-H12>0,L12-N12>0),AND(G12-H12<0,L12-N12<0),AND(G12-H12=0,L12-N12=0)),L12>-1,N12>-1),1,0) -> 1 | R12: =IF(AND(G12=L12,H12=N12,L12>-1,G12>-1),3,0) -> 3 | S12: =Q12+R12 -> 4
A13: 18 | B13: 44890 | D13: Qatar | I13: Senegal | L13: =OFICIAL!G8 -> 0 | M13: =OFICIAL!G8 -> 0 | N13: =OFICIAL!H8 -> 0 | O13: =OFICIAL!I8 -> Senegal | Q13: =IF(AND(OR(AND(G13-H13>0,L13-N13>0),AND(G13-H13<0,L13-N13<0),AND(G13-H13=0,L13-N13=0)),L13>-1,N13>-1),1,0) -> 1 | R13: =IF(AND(G13=L13,H13=N13,L13>-1,G13>-1),3,0) -> 3 | S13: =Q13+R13 -> 4
A14: 19 | B14: 44890 | D14: Países Bajos | I14: Ecuador | L14: =OFICIAL!G9 -> 0 | M14: =OFICIAL!G9 -> 0 | N14: =OFICIAL!H9 -> 0 | O14: =OFICIAL!I9 -> Ecuador | Q14: =IF(AND(OR(AND(G14-H14>0,L14-N14>0),AND(G14-H14<0,L14-N14<0),AND(G14-H14=0,L14-N14=0)),L14>-1,N14>-1),1,0) -> 1 | R14: =IF(AND(G14=L14,H14=N14,L14>-1,G14>-1),3,0) -> 3 | S14: =Q14+R14 -> 4
A15: 33 | B15: 44894 | D15: Países Bajos | I15: Qatar | L15: =OFICIAL!G10 -> 0 | M15: =OFICIAL!G10 -> 0 | N15: =OFICIAL!H10 -> 0 | O15: =OFICIAL!I10 -> Qatar | Q15: =IF(AND(OR(AND(G15-H15>0,L15-N15>0),AND(G15-H15<0,L15-N15<0),AND(G15-H15=0,L15-N15=0)),L15>-1,N15>-1),1,0) -> 1 | R15: =IF(AND(G15=L15,H15=N15,L15>-1,G15>-1),3,0) -> 3 | S15: =Q15+R15 -> 4
A16: 34 | B16: 44894 | D16: Ecuador | I16: Senegal | L16: =OFICIAL!G11 -> 0 | M16: =OFICIAL!G11 -> 0 | N16: =OFICIAL!H11 -> 0 | O16: =OFICIAL!I11 -> Senegal | Q16: =IF(AND(OR(AND(G16-H16>0,L16-N16>0),AND(G16-H16<0,L16-N16<0),AND(G16-H16=0,L16-N16=0)),L16>-1,N16>-1),1,0) -> 1 | R16: =IF(AND(G16=L16,H16=N16,L16>-1,G16>-1),3,0) -> 3 | S16: =Q16+R16 -> 4
A17: Grupo B
A18: 2 | B18: 44886 | D18: Inglaterra | I18: Irán | L18: =OFICIAL!G13 -> 0 | M18: =OFICIAL!G13 -> 0 | N18: =OFICIAL!H13 -> 0 | O18: =OFICIAL!I13 -> Irán | Q18: =IF(AND(OR(AND(G18-H18>0,L18-N18>0),AND(G18-H18<0,L18-N18<0),AND(G18-H18=0,L18-N18=0)),L18>-1,N18>-1),1,0) -> 1 | R18: =IF(AND(G18=L18,H18=N18,L18>-1,G18>-1),3,0) -> 3 | S18: =Q18+R18 -> 4
A19: 4 | B19: 44886 | D19: USA | I19: Gales | L19: =OFICIAL!G14 -> 0 | M19: =OFICIAL!G14 -> 0 | N19: =OFICIAL!H14 -> 0 | O19: =OFICIAL!I14 -> Gales | Q19: =IF(AND(OR(AND(G19-H19>0,L19-N19>0),AND(G19-H19<0,L19-N19<0),AND(G19-H19=0,L19-N19=0)),L19>-1,N19>-1),1,0) -> 1 | R19: =IF(AND(G19=L19,H19=N19,L19>-1,G19>-1),3,0) -> 3 | S19: =Q19+R19 -> 4
A20: 17 | B20: 44890 | D20: Gales | I20: Irán | L20: =OFICIAL!G15 -> 0 | M20: =OFICIAL!G15 -> 0 | N20: =OFICIAL!H15 -> 0 | O20: =OFICIAL!I15 -> Irán | Q20: =IF(AND(OR(AND(G20-H20>0,L20-N20>0),AND(G20-H20<0,L20-N20<0),AND(G20-H20=0,L20-N20=0)),L20>-1,N20>-1),1,0) -> 1 | R20: =IF(AND(G20=L20,H20=N20,L20>-1,G20>-1),3,0) -> 3 | S20: =Q20+R20 -> 4
A21: 20 | B21: 44890 | D21: Inglaterra | I21: USA | L21: =OFICIAL!G16 -> 0 | M21: =OFICIAL!G16 -> 0 | N21: =OFICIAL!H16 -> 0 | O21: =OFICIAL!I16 -> USA | Q21: =IF(AND(OR(AND(G21-H21>0,L21-N21>0),AND(G21-H21<0,L21-N21<0),AND(G21-H21=0,L21-N21=0)),L21>-1,N21>-1),1,0) -> 1 | R21: =IF(AND(G21=L21,H21=N21,L21>-1,G21>-1),3,0) -> 3 | S21: =Q21+R21 -> 4
A22: 35 | B22: 44894 | D22: Gales | I22: Inglaterra | L22: =OFICIAL!G17 -> 0 | M22: =OFICIAL!G17 -> 0 | N22: =OFICIAL!H17 -> 0 | O22: =OFICIAL!I17 -> Inglaterra | Q22: =IF(AND(OR(AND(G22-H22>0,L22-N22>0),AND(G22-H22<0,L22-N22<0),AND(G22-H22=0,L22-N22=0)),L22>-1,N22>-1),1,0) -> 1 | R22: =IF(AND(G22=L22,H22=N22,L22>-1,G22>-1),3,0) -> 3 | S22: =Q22+R22 -> 4
A23: 36 | B23: 44894 | D23: Irán | I23: USA | L23: =OFICIAL!G18 -> 0 | M23: =OFICIAL!G18 -> 0 | N23: =OFICIAL!H18 -> 0 | O23: =OFICIAL!I18 -> USA | Q23: =IF(AND(OR(AND(G23-H23>0,L23-N23>0),AND(G23-H23<0,L23-N23<0),AND(G23-H23=0,L23-N23=0)),L23>-1,N23>-1),1,0) -> 1 | R23: =IF(AND(G23=L23,H23=N23,L23>-1,G23>-1),3,0) -> 3 | S23: =Q23+R23 -> 4
A24: Grupo C
A25: 5 | B25: 44887 | D25: Argentina | I25: Arabia Saudí | L25: =OFICIAL!G20 -> 0 | M25: =OFICIAL!G20 -> 0 | N25: =OFICIAL!H20 -> 0 | O25: =OFICIAL!I20 -> Arabia Saudí | Q25: =IF(AND(OR(AND(G25-H25>0,L25-N25>0),AND(G25-H25<0,L25-N25<0),AND(G25-H25=0,L25-N25=0)),L25>-1,N25>-1),1,0) -> 1 | R25: =IF(AND(G25=L25,H25=N25,L25>-1,G25>-1),3,0) -> 3 | S25: =Q25+R25 -> 4
A26: 7 | B26: 44887 | D26: México | I26: Polonia | L26: =OFICIAL!G21 -> 0 | M26: =OFICIAL!G21 -> 0 | N26: =OFICIAL!H21 -> 0 | O26: =OFICIAL!I21 -> Polonia | Q26: =IF(AND(OR(AND(G26-H26>0,L26-N26>0),AND(G26-H26<0,L26-N26<0),AND(G26-H26=0,L26-N26=0)),L26>-1,N26>-1),1,0) -> 1 | R26: =IF(AND(G26=L26,H26=N26,L26>-1,G26>-1),3,0) -> 3 | S26: =Q26+R26 -> 4
A27: 22 | B27: 44891 | D27: Polonia | I27: Arabia Saudí | L27: =OFICIAL!G22 -> 0 | M27: =OFICIAL!G22 -> 0 | N27: =OFICIAL!H22 -> 0 | O27: =OFICIAL!I22 -> Arabia Saudí | Q27: =IF(AND(OR(AND(G27-H27>0,L27-N27>0),AND(G27-H27<0,L27-N27<0),AND(G27-H27=0,L27-N27=0)),L27>-1,N27>-1),1,0) -> 1 | R27: =IF(AND(G27=L27,H27=N27,L27>-1,G27>-1),3,0) -> 3 | S27: =Q27+R27 -> 4
A28: 24 | B28: 44891 | D28: Argentina | I28: México | L28: =OFICIAL!G23 -> 0 | M28: =OFICIAL!G23 -> 0 | N28: =OFICIAL!H23 -> 0 | O28: =OFICIAL!I23 -> México | Q28: =IF(AND(OR(AND(G28-H28>0,L28-N28>0),AND(G28-H28<0,L28-N28<0),AND(G28-H28=0,L28-N28=0)),L28>-1,N28>-1),1,0) -> 1 | R28: =IF(AND(G28=L28,H28=N28,L28>-1,G28>-1),3,0) -> 3 | S28: =Q28+R28 -> 4
A29: 39 | B29: 44895 | D29: Arabia Saudí | I29: México | L29: =OFICIAL!G24 -> 0 | M29: =OFICIAL!G24 -> 0 | N29: =OFICIAL!H24 -> 0 | O29: =OFICIAL!I24 -> México | Q29: =IF(AND(OR(AND(G29-H29>0,L29-N29>0),AND(G29-H29<0,L29-N29<0),AND(G29-H29=0,L29-N29=0)),L29>-1,N29>-1),1,0) -> 1 | R29: =IF(AND(G29=L29,H29=N29,L29>-1,G29>-1),3,0) -> 3 | S29: =Q29+R29 -> 4
A30: 40 | B30: 44895 | D30: Polonia | I30: Argentina | L30: =OFICIAL!G25 -> 0 | M30: =OFICIAL!G25 -> 0 | N30: =OFICIAL!H25 -> 0 | O30: =OFICIAL!I25 -> Argentina | Q30: =IF(AND(OR(AND(G30-H30>0,L30-N30>0),AND(G30-H30<0,L30-N30<0),AND(G30-H30=0,L30-N30=0)),L30>-1,N30>-1),1,0) -> 1 | R30: =IF(AND(G30=L30,H30=N30,L30>-1,G30>-1),3,0) -> 3 | S30: =Q30+R30 -> 4
A31: Grupo D
A32: 6 | B32: 44887 | D32: Dinamarca | I32: Túnez | L32: =OFICIAL!G27 -> 0 | M32: =OFICIAL!G27 -> 0 | N32: =OFICIAL!H27 -> 0 | O32: =OFICIAL!I27 -> Túnez | Q32: =IF(AND(OR(AND(G32-H32>0,L32-N32>0),AND(G32-H32<0,L32-N32<0),AND(G32-H32=0,L32-N32=0)),L32>-1,N32>-1),1,0) -> 1 | R32: =IF(AND(G32=L32,H32=N32,L32>-1,G32>-1),3,0) -> 3 | S32: =Q32+R32 -> 4
A33: 8 | B33: 44887 | D33: Francia | I33: Australia | L33: =OFICIAL!G28 -> 0 | M33: =OFICIAL!G28 -> 0 | N33: =OFICIAL!H28 -> 0 | O33: =OFICIAL!I28 -> Australia | Q33: =IF(AND(OR(AND(G33-H33>0,L33-N33>0),AND(G33-H33<0,L33-N33<0),AND(G33-H33=0,L33-N33=0)),L33>-1,N33>-1),1,0) -> 1 | R33: =IF(AND(G33=L33,H33=N33,L33>-1,G33>-1),3,0) -> 3 | S33: =Q33+R33 -> 4
A34: 21 | B34: 44891 | D34: Túnez | I34: Australia | L34: =OFICIAL!G29 -> 0 | M34: =OFICIAL!G29 -> 0 | N34: =OFICIAL!H29 -> 0 | O34: =OFICIAL!I29 -> Australia | Q34: =IF(AND(OR(AND(G34-H34>0,L34-N34>0),AND(G34-H34<0,L34-N34<0),AND(G34-H34=0,L34-N34=0)),L34>-1,N34>-1),1,0) -> 1 | R34: =IF(AND(G34=L34,H34=N34,L34>-1,G34>-1),3,0) -> 3 | S34: =Q34+R34 -> 4
A35: 23 | B35: 44891 | D35: Francia | I35: Dinamarca | L35: =OFICIAL!G30 -> 0 | M35: =OFICIAL!G30 -> 0 | N35: =OFICIAL!H30 -> 0 | O35: =OFICIAL!I30 -> Dinamarca | Q35: =IF(AND(OR(AND(G35-H35>0,L35-N35>0),AND(G35-H35<0,L35-N35<0),AND(G35-H35=0,L35-N35=0)),L35>-1,N35>-1),1,0) -> 1 | R35: =IF(AND(G35=L35,H35=N35,L35>-1,G35>-1),3,0) -> 3 | S35: =Q35+R35 -> 4
A36: 37 | B36: 44895 | D36: Túnez | I36: Francia | L36: =OFICIAL!G31 -> 0 | M36: =OFICIAL!G31 -> 0 | N36: =OFICIAL!H31 -> 0 | O36: =OFICIAL!I31 -> Francia | Q36: =IF(AND(OR(AND(G36-H36>0,L36-N36>0),AND(G36-H36<0,L36-N36<0),AND(G36-H36=0,L36-N36=0)),L36>-1,N36>-1),1,0) -> 1 | R36: =IF(AND(G36=L36,H36=N36,L36>-1,G36>-1),3,0) -> 3 | S36: =Q36+R36 -> 4
A37: 38 | B37: 44895 | D37: Australia | I37: Dinamarca | L37: =OFICIAL!G32 -> 0 | M37: =OFICIAL!G32 -> 0 | N37: =OFICIAL!H32 -> 0 | O37: =OFICIAL!I32 -> Dinamarca | Q37: =IF(AND(OR(AND(G37-H37>0,L37-N37>0),AND(G37-H37<0,L37-N37<0),AND(G37-H37=0,L37-N37=0)),L37>-1,N37>-1),1,0) -> 1 | R37: =IF(AND(G37=L37,H37=N37,L37>-1,G37>-1),3,0) -> 3 | S37: =Q37+R37 -> 4
A38: Grupo E
A39: 10 | B39: 44888 | D39: Alemania | I39: Japón | L39: =OFICIAL!G34 -> 0 | M39: =OFICIAL!G34 -> 0 | N39: =OFICIAL!H34 -> 0 | O39: =OFICIAL!I34 -> Japón | Q39: =IF(AND(OR(AND(G39-H39>0,L39-N39>0),AND(G39-H39<0,L39-N39<0),AND(G39-H39=0,L39-N39=0)),L39>-1,N39>-1),1,0) -> 1 | R39: =IF(AND(G39=L39,H39=N39,L39>-1,G39>-1),3,0) -> 3 | S39: =Q39+R39 -> 4
A40: 11 | B40: 44888 | D40: España | I40: Costa Rica | L40: =OFICIAL!G35 -> 0 | M40: =OFICIAL!G35 -> 0 | N40: =OFICIAL!H35 -> 0 | O40: =OFICIAL!I35 -> Costa Rica | Q40: =IF(AND(OR(AND(G40-H40>0,L40-N40>0),AND(G40-H40<0,L40-N40<0),AND(G40-H40=0,L40-N40=0)),L40>-1,N40>-1),1,0) -> 1 | R40: =IF(AND(G40=L40,H40=N40,L40>-1,G40>-1),3,0) -> 3 | S40: =Q40+R40 -> 4
A41: 25 | B41: 44892 | D41: Japón | I41: Costa Rica | L41: =OFICIAL!G36 -> 0 | M41: =OFICIAL!G36 -> 0 | N41: =OFICIAL!H36 -> 0 | O41: =OFICIAL!I36 -> Costa Rica | Q41: =IF(AND(OR(AND(G41-H41>0,L41-N41>0),AND(G41-H41<0,L41-N41<0),AND(G41-H41=0,L41-N41=0)),L41>-1,N41>-1),1,0) -> 1 | R41: =IF(AND(G41=L41,H41=N41,L41>-1,G41>-1),3,0) -> 3 | S41: =Q41+R41 -> 4
A42: 28 | B42: 44892 | D42: España | I42: Alemania | L42: =OFICIAL!G37 -> 0 | M42: =OFICIAL!G37 -> 0 | N42: =OFICIAL!H37 -> 0 | O42: =OFICIAL!I37 -> Alemania | Q42: =IF(AND(OR(AND(G42-H42>0,L42-N42>0),AND(G42-H42<0,L42-N42<0),AND(G42-H42=0,L42-N42=0)),L42>-1,N42>-1),1,0) -> 1 | R42: =IF(AND(G42=L42,H42=N42,L42>-1,G42>-1),3,0) -> 3 | S42: =Q42+R42 -> 4
...

Sheet creuaments
A3: 1A | H3: 1B
A4: 2B | B4: XXXX | G4: XXXX | H4: 2A
C6: XXXX | F6: XXXX
A8: 1C | B8: XXXX | G8: XXXX | H8: 1D
A9: 2D | H9: 2C
D11: XXXX | E11: XXXX
A13: 1E | H13: 1F
A14: 2F | B14: XXXX | G14: XXXX | H14: 2E
C16: XXXX | F16: XXXX
A18: 1G | B18: XXXX | G18: XXXX | H18: 1H
A19: 2H | H19: 2G

Sheet SMJ
B1: MUNDIAL DE FÚTBOL QATAR 2022 | O1: Premios | Q1: 1 Puesto | S1: 0.7
B2: Escribir solo en las cajas | E2: VERDES | L2: 5 | M2: E | Q2: 2 Puesto | S2: 0.2
B3: No toque ni re formatee nada | Q3: 3 Puesto | S3: 0.1
B5: PARTICIPANTE: | C5: JORDI SERRAHIMA | L5: Resultado: 1 Pt | Q5: No tocar Columnas
L6: Exacto: 4 Pts | Q6: Naranjas
A8: Partido | B8: Fecha | G8: Resultado | L8: Resultado | Q8: Pts
G9: Suyo | L9: Real | Q9: Resu | R9: Exac | S9: Total
A10: Grupo A
A11: 1 | B11: 44885 | D11: Qatar | G11: 1 | H11: 3 | I11: Ecuador | L11: =OFICIAL!G6 -> 0 | M11: =OFICIAL!G6 -> 0 | N11: =OFICIAL!H6 -> 2 | O11: =OFICIAL!I6 -> Ecuador | Q11: =IF(AND(OR(AND(G11-H11>0,L11-N11>0),AND(G11-H11<0,L11-N11<0),AND(G11-H11=0,L11-N11=0)),L11>-1,N11>-1),1,0) -> 1 | R11: =IF(AND(G11=L11,H11=N11,L11>-1,G11>-1),3,0) -> 0 | S11: =Q11+R11 -> 1
A12: 3 | B12: 44886 | D12: Senegal | G12: 0 | H12: 4 | I12: Países Bajos | L12: =OFICIAL!G7 -> 0 | M12: =OFICIAL!G7 -> 0 | N12: =OFICIAL!H7 -> 0 | O12: =OFICIAL!I7 -> Países Bajos | Q12: =IF(AND(OR(AND(G12-H12>0,L12-N12>0),AND(G12-H12<0,L12-N12<0),AND(G12-H12=0,L12-N12=0)),L12>-1,N12>-1),1,0) -> 0 | R12: =IF(AND(G12=L12,H12=N12,L12>-1,G12>-1),3,0) -> 0 | S12: =Q12+R12 -> 0
A13: 18 | B13: 44890 | D13: Qatar | G13: 1 | H13: 0 | I13: Senegal | L13: =OFICIAL!G8 -> 0 | M13: =OFICIAL!G8 -> 0 | N13: =OFICIAL!H8 -> 0 | O13: =OFICIAL!I8 -> Senegal | Q13: =IF(AND(OR(AND(G13-H13>0,L13-N13>0),AND(G13-H13<0,L13-N13<0),AND(G13-H13=0,L13-N13=0)),L13>-1,N13>-1),1,0) -> 0 | R13: =IF(AND(G13=L13,H13=N13,L13>-1,G13>-1),3,0) -> 0 | S13: =Q13+R13 -> 0
A14: 19 | B14: 44890 | D14: Países Bajos | G14: 2 | H14: 0 | I14: Ecuador | L14: =OFICIAL!G9 -> 0 | M14: =OFICIAL!G9 -> 0 | N14: =OFICIAL!H9 -> 0 | O14: =OFICIAL!I9 -> Ecuador | Q14: =IF(AND(OR(AND(G14-H14>0,L14-N14>0),AND(G14-H14<0,L14-N14<0),AND(G14-H14=0,L14-N14=0)),L14>-1,N14>-1),1,0) -> 0 | R14: =IF(AND(G14=L14,H14=N14,L14>-1,G14>-1),3,0) -> 0 | S14: =Q14+R14 -> 0
A15: 33 | B15: 44894 | D15: Países Bajos | G15: 2 | H15: 1 | I15: Qatar | L15: =OFICIAL!G10 -> 0 | M15: =OFICIAL!G10 -> 0 | N15: =OFICIAL!H10 -> 0 | O15: =OFICIAL!I10 -> Qatar | Q15: =IF(AND(OR(AND(G15-H15>0,L15-N15>0),AND(G15-H15<0,L15-N15<0),AND(G15-H15=0,L15-N15=0)),L15>-1,N15>-1),1,0) -> 0 | R15: =IF(AND(G15=L15,H15=N15,L15>-1,G15>-1),3,0) -> 0 | S15: =Q15+R15 -> 0
A16: 34 | B16: 44894 | D16: Ecuador | G16: 2 | H16: 1 | I16: Senegal | L16: =OFICIAL!G11 -> 0 | M16: =OFICIAL!G11 -> 0 | N16: =OFICIAL!H11 -> 0 | O16: =OFICIAL!I11 -> Senegal | Q16: =IF(AND(OR(AND(G16-H16>0,L16-N16>0),AND(G16-H16<0,L16-N16<0),AND(G16-H16=0,L16-N16=0)),L16>-1,N16>-1),1,0) -> 0 | R16: =IF(AND(G16=L16,H16=N16,L16>-1,G16>-1),3,0) -> 0 | S16: =Q16+R16 -> 0
A17: Grupo B
A18: 2 | B18: 44886 | D18: Inglaterra | G18: 3 | H18: 1 | I18: Irán | L18: =OFICIAL!G13 -> 0 | M18: =OFICIAL!G13 -> 0 | N18: =OFICIAL!H13 -> 0 | O18: =OFICIAL!I13 -> Irán | Q18: =IF(AND(OR(AND(G18-H18>0,L18-N18>0),AND(G18-H18<0,L18-N18<0),AND(G18-H18=0,L18-N18=0)),L18>-1,N18>-1),1,0) -> 0 | R18: =IF(AND(G18=L18,H18=N18,L18>-1,G18>-1),3,0) -> 0 | S18: =Q18+R18 -> 0
A19: 4 | B19: 44886 | D19: USA | G19: 1 | H19: 1 | I19: Gales | L19: =OFICIAL!G14 -> 0 | M19: =OFICIAL!G14 -> 0 | N19: =OFICIAL!H14 -> 0 | O19: =OFICIAL!I14 -> Gales | Q19: =IF(AND(OR(AND(G19-H19>0,L19-N19>0),AND(G19-H19<0,L19-N19<0),AND(G19-H19=0,L19-N19=0)),L19>-1,N19>-1),1,0) -> 1 | R19: =IF(AND(G19=L19,H19=N19,L19>-1,G19>-1),3,0) -> 0 | S19: =Q19+R19 -> 1
A20: 17 | B20: 44890 | D20: Gales | G20: 2 | H20: 0 | I20: Irán | L20: =OFICIAL!G15 -> 0 | M20: =OFICIAL!G15 -> 0 | N20: =OFICIAL!H15 -> 0 | O20: =OFICIAL!I15 -> Irán | Q20: =IF(AND(OR(AND(G20-H20>0,L20-N20>0),AND(G20-H20<0,L20-N20<0),AND(G20-H20=0,L20-N20=0)),L20>-1,N20>-1),1,0) -> 0 | R20: =IF(AND(G20=L20,H20=N20,L20>-1,G20>-1),3,0) -> 0 | S20: =Q20+R20 -> 0
A21: 20 | B21: 44890 | D21: Inglaterra | G21: 2 | H21: 0 | I21: USA | L21: =OFICIAL!G16 -> 0 | M21: =OFICIAL!G16 -> 0 | N21: =OFICIAL!H16 -> 0 | O21: =OFICIAL!I16 -> USA | Q21: =IF(AND(OR(AND(G21-H21>0,L21-N21>0),AND(G21-H21<0,L21-N21<0),AND(G21-H21=0,L21-N21=0)),L21>-1,N21>-1),1,0) -> 0 | R21: =IF(AND(G21=L21,H21=N21,L21>-1,G21>-1),3,0) -> 0 | S21: =Q21+R21 -> 0
A22: 35 | B22: 44894 | D22: Gales | G22: 1 | H22: 1 | I22: Inglaterra | L22: =OFICIAL!G17 -> 0 | M22: =OFICIAL!G17 -> 0 | N22: =OFICIAL!H17 -> 0 | O22: =OFICIAL!I17 -> Inglaterra | Q22: =IF(AND(OR(AND(G22-H22>0,L22-N22>0),AND(G22-H22<0,L22-N22<0),AND(G22-H22=0,L22-N22=0)),L22>-1,N22>-1),1,0) -> 1 | R22: =IF(AND(G22=L22,H22=N22,L22>-1,G22>-1),3,0) -> 0 | S22: =Q22+R22 -> 1
A23: 36 | B23: 44894 | D23: Irán | G23: 1 | H23: 2 | I23: USA | L23: =OFICIAL!G18 -> 0 | M23: =OFICIAL!G18 -> 0 | N23: =OFICIAL!H18 -> 0 | O23: =OFICIAL!I18 -> USA | Q23: =IF(AND(OR(AND(G23-H23>0,L23-N23>0),AND(G23-H23<0,L23-N23<0),AND(G23-H23=0,L23-N23=0)),L23>-1,N23>-1),1,0) -> 0 | R23: =IF(AND(G23=L23,H23=N23,L23>-1,G23>-1),3,0) -> 0 | S23: =Q23+R23 -> 0
A24: Grupo C
A25: 5 | B25: 44887 | D25: Argentina | G25: 3 | H25: 0 | I25: Arabia Saudí | L25: =OFICIAL!G20 -> 0 | M25: =OFICIAL!G20 -> 0 | N25: =OFICIAL!H20 -> 0 | O25: =OFICIAL!I20 -> Arabia Saudí | Q25: =IF(AND(OR(AND(G25-H25>0,L25-N25>0),AND(G25-H25<0,L25-N25<0),AND(G25-H25=0,L25-N25=0)),L25>-1,N25>-1),1,0) -> 0 | R25: =IF(AND(G25=L25,H25=N25,L25>-1,G25>-1),3,0) -> 0 | S25: =Q25+R25 -> 0
A26: 7 | B26: 44887 | D26: México | G26: 1 | H26: 2 | I26: Polonia | L26: =OFICIAL!G21 -> 0 | M26: =OFICIAL!G21 -> 0 | N26: =OFICIAL!H21 -> 0 | O26: =OFICIAL!I21 -> Polonia | Q26: =IF(AND(OR(AND(G26-H26>0,L26-N26>0),AND(G26-H26<0,L26-N26<0),AND(G26-H26=0,L26-N26=0)),L26>-1,N26>-1),1,0) -> 0 | R26: =IF(AND(G26=L26,H26=N26,L26>-1,G26>-1),3,0) -> 0 | S26: =Q26+R26 -> 0
A27: 22 | B27: 44891 | D27: Polonia | G27: 2 | H27: 0 | I27: Arabia Saudí | L27: =OFICIAL!G22 -> 0 | M27: =OFICIAL!G22 -> 0 | N27: =OFICIAL!H22 -> 0 | O27: =OFICIAL!I22 -> Arabia Saudí | Q27: =IF(AND(OR(AND(G27-H27>0,L27-N27>0),AND(G27-H27<0,L27-N27<0),AND(G27-H27=0,L27-N27=0)),L27>-1,N27>-1),1,0) -> 0 | R27: =IF(AND(G27=L27,H27=N27,L27>-1,G27>-1),3,0) -> 0 | S27: =Q27+R27 -> 0
A28: 24 | B28: 44891 | D28: Argentina | G28: 1 | H28: 0 | I28: México | L28: =OFICIAL!G23 -> 0 | M28: =OFICIAL!G23 -> 0 | N28: =OFICIAL!H23 -> 0 | O28: =OFICIAL!I23 -> México | Q28: =IF(AND(OR(AND(G28-H28>0,L28-N28>0),AND(G28-H28<0,L28-N28<0),AND(G28-H28=0,L28-N28=0)),L28>-1,N28>-1),1,0) -> 0 | R28: =IF(AND(G28=L28,H28=N28,L28>-1,G28>-1),3,0) -> 0 | S28: =Q28+R28 -> 0
A29: 39 | B29: 44895 | D29: Arabia Saudí | G29: 0 | H29: 2 | I29: México | L29: =OFICIAL!G24 -> 0 | M29: =OFICIAL!G24 -> 0 | N29: =OFICIAL!H24 -> 0 | O29: =OFICIAL!I24 -> México | Q29: =IF(AND(OR(AND(G29-H29>0,L29-N29>0),AND(G29-H29<0,L29-N29<0),AND(G29-H29=0,L29-N29=0)),L29>-1,N29>-1),1,0) -> 0 | R29: =IF(AND(G29=L29,H29=N29,L29>-1,G29>-1),3,0) -> 0 | S29: =Q29+R29 -> 0
A30: 40 | B30: 44895 | D30: Polonia | G30: 1 | H30: 2 | I30: Argentina | L30: =OFICIAL!G25 -> 0 | M30: =OFICIAL!G25 -> 0 | N30: =OFICIAL!H25 -> 0 | O30: =OFICIAL!I25 -> Argentina | Q30: =IF(AND(OR(AND(G30-H30>0,L30-N30>0),AND(G30-H30<0,L30-N30<0),AND(G30-H30=0,L30-N30=0)),L30>-1,N30>-1),1,0) -> 0 | R30: =IF(AND(G30=L30,H30=N30,L30>-1,G30>-1),3,0) -> 0 | S30: =Q30+R30 -> 0
A31: Grupo D
A32: 6 | B32: 44887 | D32: Dinamarca | G32: 2 | H32: 1 | I32: Túnez | L32: =OFICIAL!G27 -> 0 | M32: =OFICIAL!G27 -> 0 | N32: =OFICIAL!H27 -> 0 | O32: =OFICIAL!I27 -> Túnez | Q32: =IF(AND(OR(AND(G32-H32>0,L32-N32>0),AND(G32-H32<0,L32-N32<0),AND(G32-H32=0,L32-N32=0)),L32>-1,N32>-1),1,0) -> 0 | R32: =IF(AND(G32=L32,H32=N32,L32>-1,G32>-1),3,0) -> 0 | S32: =Q32+R32 -> 0
A33: 8 | B33: 44887 | D33: Francia | G33: 5 | H33: 0 | I33: Australia | L33: =OFICIAL!G28 -> 0 | M33: =OFICIAL!G28 -> 0 | N33: =OFICIAL!H28 -> 0 | O33: =OFICIAL!I28 -> Australia | Q33: =IF(AND(OR(AND(G33-H33>0,L33-N33>0),AND(G33-H33<0,L33-N33<0),AND(G33-H33=0,L33-N33=0)),L33>-1,N33>-1),1,0) -> 0 | R33: =IF(AND(G33=L33,H33=N33,L33>-1,G33>-1),3,0) -> 0 | S33: =Q33+R33 -> 0
A34: 21 | B34: 44891 | D34: Túnez | G34: 1 | H34: 0 | I34: Australia | L34: =OFICIAL!G29 -> 0 | M34: =OFICIAL!G29 -> 0 | N34: =OFICIAL!H29 -> 0 | O34: =OFICIAL!I29 -> Australia | Q34: =IF(AND(OR(AND(G34-H34>0,L34-N34>0),AND(G34-H34<0,L34-N34<0),AND(G34-H34=0,L34-N34=0)),L34>-1,N34>-1),1,0) -> 0 | R34: =IF(AND(G34=L34,H34=N34,L34>-1,G34>-1),3,0) -> 0 | S34: =Q34+R34 -> 0
A35: 23 | B35: 44891 | D35: Francia | G35: 1 | H35: 0 | I35: Dinamarca | L35: =OFICIAL!G30 -> 0 | M35: =OFICIAL!G30 -> 0 | N35: =OFICIAL!H30 -> 0 | O35: =OFICIAL!I30 -> Dinamarca | Q35: =IF(AND(OR(AND(G35-H35>0,L35-N35>0),AND(G35-H35<0,L35-N35<0),AND(G35-H35=0,L35-N35=0)),L35>-1,N35>-1),1,0) -> 0 | R35: =IF(AND(G35=L35,H35=N35,L35>-1,G35>-1),3,0) -> 0 | S35: =Q35+R35 -> 0
A36: 37 | B36: 44895 | D36: Túnez | G36: 1 | H36: 3 | I36: Francia | L36: =OFICIAL!G31 -> 0 | M36: =OFICIAL!G31 -> 0 | N36: =OFICIAL!H31 -> 0 | O36: =OFICIAL!I31 -> Francia | Q36: =IF(AND(OR(AND(G36-H36>0,L36-N36>0),AND(G36-H36<0,L36-N36<0),AND(G36-H36=0,L36-N36=0)),L36>-1,N36>-1),1,0) -> 0 | R36: =IF(AND(G36=L36,H36=N36,L36>-1,G36>-1),3,0) -> 0 | S36: =Q36+R36 -> 0
A37: 38 | B37: 44895 | D37: Australia | G37: 0 | H37: 2 | I37: Dinamarca | L37: =OFICIAL!G32 -> 0 | M37: =OFICIAL!G32 -> 0 | N37: =OFICIAL!H32 -> 0 | O37: =OFICIAL!I32 -> Dinamarca | Q37: =IF(AND(OR(AND(G37-H37>0,L37-N37>0),AND(G37-H37<0,L37-N37<0),AND(G37-H37=0,L37-N37=0)),L37>-1,N37>-1),1,0) -> 0 | R37: =IF(AND(G37=L37,H37=N37,L37>-1,G37>-1),3,0) -> 0 | S37: =Q37+R37 -> 0
A38: Grupo E
A39: 10 | B39: 44888 | D39: Alemania | G39: 3 | H39: 0 | I39: Japón | L39: =OFICIAL!G34 -> 0 | M39: =OFICIAL!G34 -> 0 | N39: =OFICIAL!H34 -> 0 | O39: =OFICIAL!I34 -> Japón | Q39: =IF(AND(OR(AND(G39-H39>0,L39-N39>0),AND(G39-H39<0,L39-N39<0),AND(G39-H39=0,L39-N39=0)),L39>-1,N39>-1),1,0) -> 0 | R39: =IF(AND(G39=L39,H39=N39,L39>-1,G39>-1),3,0) -> 0 | S39: =Q39+R39 -> 0
A40: 11 | B40: 44888 | D40: España | G40: 3 | H40: 1 | I40: Costa Rica | L40: =OFICIAL!G35 -> 0 | M40: =OFICIAL!G35 -> 0 | N40: =OFICIAL!H35 -> 0 | O40: =OFICIAL!I35 -> Costa Rica | Q40: =IF(AND(OR(AND(G40-H40>0,L40-N40>0),AND(G40-H40<0,L40-N40<0),AND(G40-H40=0,L40-N40=0)),L40>-1,N40>-1),1,0) -> 0 | R40: =IF(AND(G40=L40,H40=N40,L40>-1,G40>-1),3,0) -> 0 | S40: =Q40+R40 -> 0
A41: 25 | B41: 44892 | D41: Japón | G41: 2 | H41: 1 | I41: Costa Rica | L41: =OFICIAL!G36 -> 0 | M41: =OFICIAL!G36 -> 0 | N41: =OFICIAL!H36 -> 0 | O41: =OFICIAL!I36 -> Costa Rica | Q41: =IF(AND(OR(AND(G41-H41>0,L41-N41>0),AND(G41-H41<0,L41-N41<0),AND(G41-H41=0,L41-N41=0)),L41>-1,N41>-1),1,0) -> 0 | R41: =IF(AND(G41=L41,H41=N41,L41>-1,G41>-1),3,0) -> 0 | S41: =Q41+R41 -> 0
A42: 28 | B42: 44892 | D42: España | G42: 1 | H42: 1 | I42: Alemania | L42: =OFICIAL!G37 -> 0 | M42: =OFICIAL!G37 -> 0 | N42: =OFICIAL!H37 -> 0 | O42: =OFICIAL!I37 -> Alemania | Q42: =IF(AND(OR(AND(G42-H42>0,L42-N42>0),AND(G42-H42<0,L42-N42<0),AND(G42-H42=0,L42-N42=0)),L42>-1,N42>-1),1,0) -> 1 | R42: =IF(AND(G42=L42,H42=N42,L42>-1,G42>-1),3,0) -> 0 | S42: =Q42+R42 -> 1
...

Sheet AJD
B1: MUNDIAL DE FÚTBOL QATAR 2022 | O1: Premios | Q1: 1 Puesto | S1: 0.7
B2: Escribir solo en las cajas | E2: VERDES | L2: 5 | M2: E | Q2: 2 Puesto | S2: 0.2
B3: No toque ni re formatee nada | Q3: 3 Puesto | S3: 0.1
B5: PARTICIPANTE: | C5: ANTONIO BARRIAS | L5: Resultado: 1 Pt | Q5: No tocar Columnas
L6: Exacto: 4 Pts | Q6: Naranjas
A8: Partido | B8: Fecha | G8: Resultado | L8: Resultado | Q8: Pts
G9: Suyo | L9: Real | Q9: Resu | R9: Exac | S9: Total
A10: Grupo A
A11: 1 | B11: 44885 | D11: Qatar | G11: 0 | H11: 2 | I11: Ecuador | L11: =OFICIAL!G6 -> 0 | M11: =OFICIAL!G6 -> 0 | N11: =OFICIAL!H6 -> 2 | O11: =OFICIAL!I6 -> Ecuador | Q11: =IF(AND(OR(AND(G11-H11>0,L11-N11>0),AND(G11-H11<0,L11-N11<0),AND(G11-H11=0,L11-N11=0)),L11>-1,N11>-1),1,0) -> 1 | R11: =IF(AND(G11=L11,H11=N11,L11>-1,G11>-1),3,0) -> 3 | S11: =Q11+R11 -> 4
A12: 3 | B12: 44886 | D12: Senegal | G12: 1 | H12: 1 | I12: Países Bajos | L12: =OFICIAL!G7 -> 0 | M12: =OFICIAL!G7 -> 0 | N12: =OFICIAL!H7 -> 0 | O12: =OFICIAL!I7 -> Países Bajos | Q12: =IF(AND(OR(AND(G12-H12>0,L12-N12>0),AND(G12-H12<0,L12-N12<0),AND(G12-H12=0,L12-N12=0)),L12>-1,N12>-1),1,0) -> 1 | R12: =IF(AND(G12=L12,H12=N12,L12>-1,G12>-1),3,0) -> 0 | S12: =Q12+R12 -> 1
A13: 18 | B13: 44890 | D13: Qatar | G13: 0 | H13: 2 | I13: Senegal | L13: =OFICIAL!G8 -> 0 | M13: =OFICIAL!G8 -> 0 | N13: =OFICIAL!H8 -> 0 | O13: =OFICIAL!I8 -> Senegal | Q13: =IF(AND(OR(AND(G13-H13>0,L13-N13>0),AND(G13-H13<0,L13-N13<0),AND(G13-H13=0,L13-N13=0)),L13>-1,N13>-1),1,0) -> 0 | R13: =IF(AND(G13=L13,H13=N13,L13>-1,G13>-1),3,0) -> 0 | S13: =Q13+R13 -> 0
A14: 19 | B14: 44890 | D14: Países Bajos | G14: 2 | H14: 1 | I14: Ecuador | L14: =OFICIAL!G9 -> 0 | M14: =OFICIAL!G9 -> 0 | N14: =OFICIAL!H9 -> 0 | O14: =OFICIAL!I9 -> Ecuador | Q14: =IF(AND(OR(AND(G14-H14>0,L14-N14>0),AND(G14-H14<0,L14-N14<0),AND(G14-H14=0,L14-N14=0)),L14>-1,N14>-1),1,0) -> 0 | R14: =IF(AND(G14=L14,H14=N14,L14>-1,G14>-1),3,0) -> 0 | S14: =Q14+R14 -> 0
A15: 33 | B15: 44894 | D15: Países Bajos | G15: 3 | H15: 0 | I15: Qatar | L15: =OFICIAL!G10 -> 0 | M15: =OFICIAL!G10 -> 0 | N15: =OFICIAL!H10 -> 0 | O15: =OFICIAL!I10 -> Qatar | Q15: =IF(AND(OR(AND(G15-H15>0,L15-N15>0),AND(G15-H15<0,L15-N15<0),AND(G15-H15=0,L15-N15=0)),L15>-1,N15>-1),1,0) -> 0 | R15: =IF(AND(G15=L15,H15=N15,L15>-1,G15>-1),3,0) -> 0 | S15: =Q15+R15 -> 0
A16: 34 | B16: 44894 | D16: Ecuador | G16: 1 | H16: 1 | I16: Senegal | L16: =OFICIAL!G11 -> 0 | M16: =OFICIAL!G11 -> 0 | N16: =OFICIAL!H11 -> 0 | O16: =OFICIAL!I11 -> Senegal | Q16: =IF(AND(OR(AND(G16-H16>0,L16-N16>0),AND(G16-H16<0,L16-N16<0),AND(G16-H16=0,L16-N16=0)),L16>-1,N16>-1),1,0) -> 1 | R16: =IF(AND(G16=L16,H16=N16,L16>-1,G16>-1),3,0) -> 0 | S16: =Q16+R16 -> 1
A17: Grupo B
A18: 2 | B18: 44886 | D18: Inglaterra | G18: 2 | H18: 0 | I18: Irán | L18: =OFICIAL!G13 -> 0 | M18: =OFICIAL!G13 -> 0 | N18: =OFICIAL!H13 -> 0 | O18: =OFICIAL!I13 -> Irán | Q18: =IF(AND(OR(AND(G18-H18>0,L18-N18>0),AND(G18-H18<0,L18-N18<0),AND(G18-H18=0,L18-N18=0)),L18>-1,N18>-1),1,0) -> 0 | R18: =IF(AND(G18=L18,H18=N18,L18>-1,G18>-1),3,0) -> 0 | S18: =Q18+R18 -> 0
A19: 4 | B19: 44886 | D19: USA | G19: 1 | H19: 1 | I19: Gales | L19: =OFICIAL!G14 -> 0 | M19: =OFICIAL!G14 -> 0 | N19: =OFICIAL!H14 -> 0 | O19: =OFICIAL!I14 -> Gales | Q19: =IF(AND(OR(AND(G19-H19>0,L19-N19>0),AND(G19-H19<0,L19-N19<0),AND(G19-H19=0,L19-N19=0)),L19>-1,N19>-1),1,0) -> 1 | R19: =IF(AND(G19=L19,H19=N19,L19>-1,G19>-1),3,0) -> 0 | S19: =Q19+R19 -> 1
A20: 17 | B20: 44890 | D20: Gales | G20: 1 | H20: 0 | I20: Irán | L20: =OFICIAL!G15 -> 0 | M20: =OFICIAL!G15 -> 0 | N20: =OFICIAL!H15 -> 0 | O20: =OFICIAL!I15 -> Irán | Q20: =IF(AND(OR(AND(G20-H20>0,L20-N20>0),AND(G20-H20<0,L20-N20<0),AND(G20-H20=0,L20-N20=0)),L20>-1,N20>-1),1,0) -> 0 | R20: =IF(AND(G20=L20,H20=N20,L20>-1,G20>-1),3,0) -> 0 | S20: =Q20+R20 -> 0
A21: 20 | B21: 44890 | D21: Inglaterra | G21: 3 | H21: 2 | I21: USA | L21: =OFICIAL!G16 -> 0 | M21: =OFICIAL!G16 -> 0 | N21: =OFICIAL!H16 -> 0 | O21: =OFICIAL!I16 -> USA | Q21: =IF(AND(OR(AND(G21-H21>0,L21-N21>0),AND(G21-H21<0,L21-N21<0),AND(G21-H21=0,L21-N21=0)),L21>-1,N21>-1),1,0) -> 0 | R21: =IF(AND(G21=L21,H21=N21,L21>-1,G21>-1),3,0) -> 0 | S21: =Q21+R21 -> 0
A22: 35 | B22: 44894 | D22: Gales | G22: 1 | H22: 2 | I22: Inglaterra | L22: =OFICIAL!G17 -> 0 | M22: =OFICIAL!G17 -> 0 | N22: =OFICIAL!H17 -> 0 | O22: =OFICIAL!I17 -> Inglaterra | Q22: =IF(AND(OR(AND(G22-H22>0,L22-N22>0),AND(G22-H22<0,L22-N22<0),AND(G22-H22=0,L22-N22=0)),L22>-1,N22>-1),1,0) -> 0 | R22: =IF(AND(G22=L22,H22=N22,L22>-1,G22>-1),3,0) -> 0 | S22: =Q22+R22 -> 0
A23: 36 | B23: 44894 | D23: Irán | G23: 1 | H23: 3 | I23: USA | L23: =OFICIAL!G18 -> 0 | M23: =OFICIAL!G18 -> 0 | N23: =OFICIAL!H18 -> 0 | O23: =OFICIAL!I18 -> USA | Q23: =IF(AND(OR(AND(G23-H23>0,L23-N23>0),AND(G23-H23<0,L23-N23<0),AND(G23-H23=0,L23-N23=0)),L23>-1,N23>-1),1,0) -> 0 | R23: =IF(AND(G23=L23,H23=N23,L23>-1,G23>-1),3,0) -> 0 | S23: =Q23+R23 -> 0
A24: Grupo C
A25: 5 | B25: 44887 | D25: Argentina | G25: 3 | H25: 0 | I25: Arabia Saudí | L25: =OFICIAL!G20 -> 0 | M25: =OFICIAL!G20 -> 0 | N25: =OFICIAL!H20 -> 0 | O25: =OFICIAL!I20 -> Arabia Saudí | Q25: =IF(AND(OR(AND(G25-H25>0,L25-N25>0),AND(G25-H25<0,L25-N25<0),AND(G25-H25=0,L25-N25=0)),L25>-1,N25>-1),1,0) -> 0 | R25: =IF(AND(G25=L25,H25=N25,L25>-1,G25>-1),3,0) -> 0 | S25: =Q25+R25 -> 0
A26: 7 | B26: 44887 | D26: México | G26: 1 | H26: 1 | I26: Polonia | L26: =OFICIAL!G21 -> 0 | M26: =OFICIAL!G21 -> 0 | N26: =OFICIAL!H21 -> 0 | O26: =OFICIAL!I21 -> Polonia | Q26: =IF(AND(OR(AND(G26-H26>0,L26-N26>0),AND(G26-H26<0,L26-N26<0),AND(G26-H26=0,L26-N26=0)),L26>-1,N26>-1),1,0) -> 1 | R26: =IF(AND(G26=L26,H26=N26,L26>-1,G26>-1),3,0) -> 0 | S26: =Q26+R26 -> 1
A27: 22 | B27: 44891 | D27: Polonia | G27: 3 | H27: 1 | I27: Arabia Saudí | L27: =OFICIAL!G22 -> 0 | M27: =OFICIAL!G22 -> 0 | N27: =OFICIAL!H22 -> 0 | O27: =OFICIAL!I22 -> Arabia Saudí | Q27: =IF(AND(OR(AND(G27-H27>0,L27-N27>0),AND(G27-H27<0,L27-N27<0),AND(G27-H27=0,L27-N27=0)),L27>-1,N27>-1),1,0) -> 0 | R27: =IF(AND(G27=L27,H27=N27,L27>-1,G27>-1),3,0) -> 0 | S27: =Q27+R27 -> 0
A28: 24 | B28: 44891 | D28: Argentina | G28: 3 | H28: 1 | I28: México | L28: =OFICIAL!G23 -> 0 | M28: =OFICIAL!G23 -> 0 | N28: =OFICIAL!H23 -> 0 | O28: =OFICIAL!I23 -> México | Q28: =IF(AND(OR(AND(G28-H28>0,L28-N28>0),AND(G28-H28<0,L28-N28<0),AND(G28-H28=0,L28-N28=0)),L28>-1,N28>-1),1,0) -> 0 | R28: =IF(AND(G28=L28,H28=N28,L28>-1,G28>-1),3,0) -> 0 | S28: =Q28+R28 -> 0
A29: 39 | B29: 44895 | D29: Arabia Saudí | G29: 1 | H29: 3 | I29: México | L29: =OFICIAL!G24 -> 0 | M29: =OFICIAL!G24 -> 0 | N29: =OFICIAL!H24 -> 0 | O29: =OFICIAL!I24 -> México | Q29: =IF(AND(OR(AND(G29-H29>0,L29-N29>0),AND(G29-H29<0,L29-N29<0),AND(G29-H29=0,L29-N29=0)),L29>-1,N29>-1),1,0) -> 0 | R29: =IF(AND(G29=L29,H29=N29,L29>-1,G29>-1),3,0) -> 0 | S29: =Q29+R29 -> 0
A30: 40 | B30: 44895 | D30: Polonia | G30: 1 | H30: 2 | I30: Argentina | L30: =OFICIAL!G25 -> 0 | M30: =OFICIAL!G25 -> 0 | N30: =OFICIAL!H25 -> 0 | O30: =OFICIAL!I25 -> Argentina | Q30: =IF(AND(OR(AND(G30-H30>0,L30-N30>0),AND(G30-H30<0,L30-N30<0),AND(G30-H30=0,L30-N30=0)),L30>-1,N30>-1),1,0) -> 0 | R30: =IF(AND(G30=L30,H30=N30,L30>-1,G30>-1),3,0) -> 0 | S30: =Q30+R30 -> 0
A31: Grupo D
A32: 6 | B32: 44887 | D32: Dinamarca | G32: 2 | H32: 0 | I32: Túnez | L32: =OFICIAL!G27 -> 0 | M32: =OFICIAL!G27 -> 0 | N32: =OFICIAL!H27 -> 0 | O32: =OFICIAL!I27 -> Túnez | Q32: =IF(AND(OR(AND(G32-H32>0,L32-N32>0),AND(G32-H32<0,L32-N32<0),AND(G32-H32=0,L32-N32=0)),L32>-1,N32>-1),1,0) -> 0 | R32: =IF(AND(G32=L32,H32=N32,L32>-1,G32>-1),3,0) -> 0 | S32: =Q32+R32 -> 0
A33: 8 | B33: 44887 | D33: Francia | G33: 3 | H33: 0 | I33: Australia | L33: =OFICIAL!G28 -> 0 | M33: =OFICIAL!G28 -> 0 | N33: =OFICIAL!H28 -> 0 | O33: =OFICIAL!I28 -> Australia | Q33: =IF(AND(OR(AND(G33-H33>0,L33-N33>0),AND(G33-H33<0,L33-N33<0),AND(G33-H33=0,L33-N33=0)),L33>-1,N33>-1),1,0) -> 0 | R33: =IF(AND(G33=L33,H33=N33,L33>-1,G33>-1),3,0) -> 0 | S33: =Q33+R33 -> 0
A34: 21 | B34: 44891 | D34: Túnez | G34: 1 | H34: 1 | I34: Australia | L34: =OFICIAL!G29 -> 0 | M34: =OFICIAL!G29 -> 0 | N34: =OFICIAL!H29 -> 0 | O34: =OFICIAL!I29 -> Australia | Q34: =IF(AND(OR(AND(G34-H34>0,L34-N34>0),AND(G34-H34<0,L34-N34<0),AND(G34-H34=0,L34-N34=0)),L34>-1,N34>-1),1,0) -> 1 | R34: =IF(AND(G34=L34,H34=N34,L34>-1,G34>-1),3,0) -> 0 | S34: =Q34+R34 -> 1
A35: 23 | B35: 44891 | D35: Francia | G35: 1 | H35: 1 | I35: Dinamarca | L35: =OFICIAL!G30 -> 0 | M35: =OFICIAL!G30 -> 0 | N35: =OFICIAL!H30 -> 0 | O35: =OFICIAL!I30 -> Dinamarca | Q35: =IF(AND(OR(AND(G35-H35>0,L35-N35>0),AND(G35-H35<0,L35-N35<0),AND(G35-H35=0,L35-N35=0)),L35>-1,N35>-1),1,0) -> 1 | R35: =IF(AND(G35=L35,H35=N35,L35>-1,G35>-1),3,0) -> 0 | S35: =Q35+R35 -> 1
A36: 37 | B36: 44895 | D36: Túnez | G36: 0 | H36: 2 | I36: Francia | L36: =OFICIAL!G31 -> 0 | M36: =OFICIAL!G31 -> 0 | N36: =OFICIAL!H31 -> 0 | O36: =OFICIAL!I31 -> Francia | Q36: =IF(AND(OR(AND(G36-H36>0,L36-N36>0),AND(G36-H36<0,L36-N36<0),AND(G36-H36=0,L36-N36=0)),L36>-1,N36>-1),1,0) -> 0 | R36: =IF(AND(G36=L36,H36=N36,L36>-1,G36>-1),3,0) -> 0 | S36: =Q36+R36 -> 0
A37: 38 | B37: 44895 | D37: Australia | G37: 1 | H37: 2 | I37: Dinamarca | L37: =OFICIAL!G32 -> 0 | M37: =OFICIAL!G32 -> 0 | N37: =OFICIAL!H32 -> 0 | O37: =OFICIAL!I32 -> Dinamarca | Q37: =IF(AND(OR(AND(G37-H37>0,L37-N37>0),AND(G37-H37<0,L37-N37<0),AND(G37-H37=0,L37-N37=0)),L37>-1,N37>-1),1,0) -> 0 | R37: =IF(AND(G37=L37,H37=N37,L37>-1,G37>-1),3,0) -> 0 | S37: =Q37+R37 -> 0
A38: Grupo E
A39: 10 | B39: 44888 | D39: Alemania | G39: 3 | H39: 1 | I39: Japón | L39: =OFICIAL!G34 -> 0 | M39: =OFICIAL!G34 -> 0 | N39: =OFICIAL!H34 -> 0 | O39: =OFICIAL!I34 -> Japón | Q39: =IF(AND(OR(AND(G39-H39>0,L39-N39>0),AND(G39-H39<0,L39-N39<0),AND(G39-H39=0,L39-N39=0)),L39>-1,N39>-1),1,0) -> 0 | R39: =IF(AND(G39=L39,H39=N39,L39>-1,G39>-1),3,0) -> 0 | S39: =Q39+R39 -> 0
A40: 11 | B40: 44888 | D40: España | G40: 2 | H40: 0 | I40: Costa Rica | L40: =OFICIAL!G35 -> 0 | M40: =OFICIAL!G35 -> 0 | N40: =OFICIAL!H35 -> 0 | O40: =OFICIAL!I35 -> Costa Rica | Q40: =IF(AND(OR(AND(G40-H40>0,L40-N40>0),AND(G40-H40<0,L40-N40<0),AND(G40-H40=0,L40-N40=0)),L40>-1,N40>-1),1,0) -> 0 | R40: =IF(AND(G40=L40,H40=N40,L40>-1,G40>-1),3,0) -> 0 | S40: =Q40+R40 -> 0
A41: 25 | B41: 44892 | D41: Japón | G41: 2 | H41: 1 | I41: Costa Rica | L41: =OFICIAL!G36 -> 0 | M41: =OFICIAL!G36 -> 0 | N41: =OFICIAL!H36 -> 0 | O41: =OFICIAL!I36 -> Costa Rica | Q41: =IF(AND(OR(AND(G41-H41>0,L41-N41>0),AND(G41-H41<0,L41-N41<0),AND(G41-H41=0,L41-N41=0)),L41>-1,N41>-1),1,0) -> 0 | R41: =IF(AND(G41=L41,H41=N41,L41>-1,G41>-1),3,0) -> 0 | S41: =Q41+R41 -> 0
A42: 28 | B42: 44892 | D42: España | G42: 1 | H42: 1 | I42: Alemania | L42: =OFICIAL!G37 -> 0 | M42: =OFICIAL!G37 -> 0 | N42: =OFICIAL!H37 -> 0 | O42: =OFICIAL!I37 -> Alemania | Q42: =IF(AND(OR(AND(G42-H42>0,L42-N42>0),AND(G42-H42<0,L42-N42<0),AND(G42-H42=0,L42-N42=0)),L42>-1,N42>-1),1,0) -> 1 | R42: =IF(AND(G42=L42,H42=N42,L42>-1,G42>-1),3,0) -> 0 | S42: =Q42+R42 -> 1
...

Sheet JCB
B1: MUNDIAL DE FÚTBOL QATAR 2022 | O1: Premios | Q1: 1 Puesto | S1: 0.7
B2: Escribir solo en las cajas | E2: VERDES | L2: 5 | M2: E | Q2: 2 Puesto | S2: 0.2
B3: No toque ni re formatee nada | Q3: 3 Puesto | S3: 0.1
B5: PARTICIPANTE: | C5: JORDI CUCURULL BARGALLÓ | L5: Resultado: 1 Pt | Q5: No tocar Columnas
L6: Exacto: 4 Pts | Q6: Naranjas
A8: Partido | B8: Fecha | G8: Resultado | L8: Resultado | Q8: Pts
G9: Suyo | L9: Real | Q9: Resu | R9: Exac | S9: Total
A10: Grupo A
A11: 1 | B11: 44885 | D11: Qatar | G11: 1 | H11: 2 | I11: Ecuador | L11: =OFICIAL!G6 -> 0 | M11: =OFICIAL!G6 -> 0 | N11: =OFICIAL!H6 -> 2 | O11: =OFICIAL!I6 -> Ecuador | Q11: =IF(AND(OR(AND(G11-H11>0,L11-N11>0),AND(G11-H11<0,L11-N11<0),AND(G11-H11=0,L11-N11=0)),L11>-1,N11>-1),1,0) -> 1 | R11: =IF(AND(G11=L11,H11=N11,L11>-1,G11>-1),3,0) -> 0 | S11: =Q11+R11 -> 1
A12: 3 | B12: 44886 | D12: Senegal | G12: 1 | H12: 3 | I12: Países Bajos | L12: =OFICIAL!G7 -> 0 | M12: =OFICIAL!G7 -> 0 | N12: =OFICIAL!H7 -> 0 | O12: =OFICIAL!I7 -> Países Bajos | Q12: =IF(AND(OR(AND(G12-H12>0,L12-N12>0),AND(G12-H12<0,L12-N12<0),AND(G12-H12=0,L12-N12=0)),L12>-1,N12>-1),1,0) -> 0 | R12: =IF(AND(G12=L12,H12=N12,L12>-1,G12>-1),3,0) -> 0 | S12: =Q12+R12 -> 0
A13: 18 | B13: 44890 | D13: Qatar | G13: 0 | H13: 1 | I13: Senegal | L13: =OFICIAL!G8 -> 0 | M13: =OFICIAL!G8 -> 0 | N13: =OFICIAL!H8 -> 0 | O13: =OFICIAL!I8 -> Senegal | Q13: =IF(AND(OR(AND(G13-H13>0,L13-N13>0),AND(G13-H13<0,L13-N13<0),AND(G13-H13=0,L13-N13=0)),L13>-1,N13>-1),1,0) -> 0 | R13: =IF(AND(G13=L13,H13=N13,L13>-1,G13>-1),3,0) -> 0 | S13: =Q13+R13 -> 0
A14: 19 | B14: 44890 | D14: Países Bajos | G14: 2 | H14: 1 | I14: Ecuador | L14: =OFICIAL!G9 -> 0 | M14: =OFICIAL!G9 -> 0 | N14: =OFICIAL!H9 -> 0 | O14: =OFICIAL!I9 -> Ecuador | Q14: =IF(AND(OR(AND(G14-H14>0,L14-N14>0),AND(G14-H14<0,L14-N14<0),AND(G14-H14=0,L14-N14=0)),L14>-1,N14>-1),1,0) -> 0 | R14: =IF(AND(G14=L14,H14=N14,L14>-1,G14>-1),3,0) -> 0 | S14: =Q14+R14 -> 0
A15: 33 | B15: 44894 | D15: Países Bajos | G15: 3 | H15: 0 | I15: Qatar | L15: =OFICIAL!G10 -> 0 | M15: =OFICIAL!G10 -> 0 | N15: =OFICIAL!H10 -> 0 | O15: =OFICIAL!I10 -> Qatar | Q15: =IF(AND(OR(AND(G15-H15>0,L15-N15>0),AND(G15-H15<0,L15-N15<0),AND(G15-H15=0,L15-N15=0)),L15>-1,N15>-1),1,0) -> 0 | R15: =IF(AND(G15=L15,H15=N15,L15>-1,G15>-1),3,0) -> 0 | S15: =Q15+R15 -> 0
A16: 34 | B16: 44894 | D16: Ecuador | G16: 2 | H16: 1 | I16: Senegal | L16: =OFICIAL!G11 -> 0 | M16: =OFICIAL!G11 -> 0 | N16: =OFICIAL!H11 -> 0 | O16: =OFICIAL!I11 -> Senegal | Q16: =IF(AND(OR(AND(G16-H16>0,L16-N16>0),AND(G16-H16<0,L16-N16<0),AND(G16-H16=0,L16-N16=0)),L16>-1,N16>-1),1,0) -> 0 | R16: =IF(AND(G16=L16,H16=N16,L16>-1,G16>-1),3,0) -> 0 | S16: =Q16+R16 -> 0
A17: Grupo B
A18: 2 | B18: 44886 | D18: Inglaterra | G18: 3 | H18: 1 | I18: Irán | L18: =OFICIAL!G13 -> 0 | M18: =OFICIAL!G13 -> 0 | N18: =OFICIAL!H13 -> 0 | O18: =OFICIAL!I13 -> Irán | Q18: =IF(AND(OR(AND(G18-H18>0,L18-N18>0),AND(G18-H18<0,L18-N18<0),AND(G18-H18=0,L18-N18=0)),L18>-1,N18>-1),1,0) -> 0 | R18: =IF(AND(G18=L18,H18=N18,L18>-1,G18>-1),3,0) -> 0 | S18: =Q18+R18 -> 0
A19: 4 | B19: 44886 | D19: USA | G19: 1 | H19: 0 | I19: Gales | L19: =OFICIAL!G14 -> 0 | M19: =OFICIAL!G14 -> 0 | N19: =OFICIAL!H14 -> 0 | O19: =OFICIAL!I14 -> Gales | Q19: =IF(AND(OR(AND(G19-H19>0,L19-N19>0),AND(G19-H19<0,L19-N19<0),AND(G19-H19=0,L19-N19=0)),L19>-1,N19>-1),1,0) -> 0 | R19: =IF(AND(G19=L19,H19=N19,L19>-1,G19>-1),3,0) -> 0 | S19: =Q19+R19 -> 0
A20: 17 | B20: 44890 | D20: Gales | G20: 3 | H20: 1 | I20: Irán | L20: =OFICIAL!G15 -> 0 | M20: =OFICIAL!G15 -> 0 | N20: =OFICIAL!H15 -> 0 | O20: =OFICIAL!I15 -> Irán | Q20: =IF(AND(OR(AND(G20-H20>0,L20-N20>0),AND(G20-H20<0,L20-N20<0),AND(G20-H20=0,L20-N20=0)),L20>-1,N20>-1),1,0) -> 0 | R20: =IF(AND(G20=L20,H20=N20,L20>-1,G20>-1),3,0) -> 0 | S20: =Q20+R20 -> 0
A21: 20 | B21: 44890 | D21: Inglaterra | G21: 2 | H21: 0 | I21: USA | L21: =OFICIAL!G16 -> 0 | M21: =OFICIAL!G16 -> 0 | N21: =OFICIAL!H16 -> 0 | O21: =OFICIAL!I16 -> USA | Q21: =IF(AND(OR(AND(G21-H21>0,L21-N21>0),AND(G21-H21<0,L21-N21<0),AND(G21-H21=0,L21-N21=0)),L21>-1,N21>-1),1,0) -> 0 | R21: =IF(AND(G21=L21,H21=N21,L21>-1,G21>-1),3,0) -> 0 | S21: =Q21+R21 -> 0
A22: 35 | B22: 44894 | D22: Gales | G22: 2 | H22: 2 | I22: Inglaterra | L22: =OFICIAL!G17 -> 0 | M22: =OFICIAL!G17 -> 0 | N22: =OFICIAL!H17 -> 0 | O22: =OFICIAL!I17 -> Inglaterra | Q22: =IF(AND(OR(AND(G22-H22>0,L22-N22>0),AND(G22-H22<0,L22-N22<0),AND(G22-H22=0,L22-N22=0)),L22>-1,N22>-1),1,0) -> 1 | R22: =IF(AND(G22=L22,H22=N22,L22>-1,G22>-1),3,0) -> 0 | S22: =Q22+R22 -> 1
A23: 36 | B23: 44894 | D23: Irán | G23: 1 | H23: 3 | I23: USA | L23: =OFICIAL!G18 -> 0 | M23: =OFICIAL!G18 -> 0 | N23: =OFICIAL!H18 -> 0 | O23: =OFICIAL!I18 -> USA | Q23: =IF(AND(OR(AND(G23-H23>0,L23-N23>0),AND(G23-H23<0,L23-N23<0),AND(G23-H23=0,L23-N23=0)),L23>-1,N23>-1),1,0) -> 0 | R23: =IF(AND(G23=L23,H23=N23,L23>-1,G23>-1),3,0) -> 0 | S23: =Q23+R23 -> 0
A24: Grupo C
A25: 5 | B25: 44887 | D25: Argentina | G25: 3 | H25: 0 | I25: Arabia Saudí | L25: =OFICIAL!G20 -> 0 | M25: =OFICIAL!G20 -> 0 | N25: =OFICIAL!H20 -> 0 | O25: =OFICIAL!I20 -> Arabia Saudí | Q25: =IF(AND(OR(AND(G25-H25>0,L25-N25>0),AND(G25-H25<0,L25-N25<0),AND(G25-H25=0,L25-N25=0)),L25>-1,N25>-1),1,0) -> 0 | R25: =IF(AND(G25=L25,H25=N25,L25>-1,G25>-1),3,0) -> 0 | S25: =Q25+R25 -> 0
A26: 7 | B26: 44887 | D26: México | G26: 1 | H26: 2 | I26: Polonia | L26: =OFICIAL!G21 -> 0 | M26: =OFICIAL!G21 -> 0 | N26: =OFICIAL!H21 -> 0 | O26: =OFICIAL!I21 -> Polonia | Q26: =IF(AND(OR(AND(G26-H26>0,L26-N26>0),AND(G26-H26<0,L26-N26<0),AND(G26-H26=0,L26-N26=0)),L26>-1,N26>-1),1,0) -> 0 | R26: =IF(AND(G26=L26,H26=N26,L26>-1,G26>-1),3,0) -> 0 | S26: =Q26+R26 -> 0
A27: 22 | B27: 44891 | D27: Polonia | G27: 2 | H27: 0 | I27: Arabia Saudí | L27: =OFICIAL!G22 -> 0 | M27: =OFICIAL!G22 -> 0 | N27: =OFICIAL!H22 -> 0 | O27: =OFICIAL!I22 -> Arabia Saudí | Q27: =IF(AND(OR(AND(G27-H27>0,L27-N27>0),AND(G27-H27<0,L27-N27<0),AND(G27-H27=0,L27-N27=0)),L27>-1,N27>-1),1,0) -> 0 | R27: =IF(AND(G27=L27,H27=N27,L27>-1,G27>-1),3,0) -> 0 | S27: =Q27+R27 -> 0
A28: 24 | B28: 44891 | D28: Argentina | G28: 2 | H28: 0 | I28: México | L28: =OFICIAL!G23 -> 0 | M28: =OFICIAL!G23 -> 0 | N28: =OFICIAL!H23 -> 0 | O28: =OFICIAL!I23 -> México | Q28: =IF(AND(OR(AND(G28-H28>0,L28-N28>0),AND(G28-H28<0,L28-N28<0),AND(G28-H28=0,L28-N28=0)),L28>-1,N28>-1),1,0) -> 0 | R28: =IF(AND(G28=L28,H28=N28,L28>-1,G28>-1),3,0) -> 0 | S28: =Q28+R28 -> 0
A29: 39 | B29: 44895 | D29: Arabia Saudí | G29: 2 | H29: 2 | I29: México | L29: =OFICIAL!G24 -> 0 | M29: =OFICIAL!G24 -> 0 | N29: =OFICIAL!H24 -> 0 | O29: =OFICIAL!I24 -> México | Q29: =IF(AND(OR(AND(G29-H29>0,L29-N29>0),AND(G29-H29<0,L29-N29<0),AND(G29-H29=0,L29-N29=0)),L29>-1,N29>-1),1,0) -> 1 | R29: =IF(AND(G29=L29,H29=N29,L29>-1,G29>-1),3,0) -> 0 | S29: =Q29+R29 -> 1
A30: 40 | B30: 44895 | D30: Polonia | G30: 1 | H30: 1 | I30: Argentina | L30: =OFICIAL!G25 -> 0 | M30: =OFICIAL!G25 -> 0 | N30: =OFICIAL!H25 -> 0 | O30: =OFICIAL!I25 -> Argentina | Q30: =IF(AND(OR(AND(G30-H30>0,L30-N30>0),AND(G30-H30<0,L30-N30<0),AND(G30-H30=0,L30-N30=0)),L30>-1,N30>-1),1,0) -> 1 | R30: =IF(AND(G30=L30,H30=N30,L30>-1,G30>-1),3,0) -> 0 | S30: =Q30+R30 -> 1
A31: Grupo D
A32: 6 | B32: 44887 | D32: Dinamarca | G32: 2 | H32: 0 | I32: Túnez | L32: =OFICIAL!G27 -> 0 | M32: =OFICIAL!G27 -> 0 | N32: =OFICIAL!H27 -> 0 | O32: =OFICIAL!I27 -> Túnez | Q32: =IF(AND(OR(AND(G32-H32>0,L32-N32>0),AND(G32-H32<0,L32-N32<0),AND(G32-H32=0,L32-N32=0)),L32>-1,N32>-1),1,0) -> 0 | R32: =IF(AND(G32=L32,H32=N32,L32>-1,G32>-1),3,0) -> 0 | S32: =Q32+R32 -> 0
A33: 8 | B33: 44887 | D33: Francia | G33: 3 | H33: 1 | I33: Australia | L33: =OFICIAL!G28 -> 0 | M33: =OFICIAL!G28 -> 0 | N33: =OFICIAL!H28 -> 0 | O33: =OFICIAL!I28 -> Australia | Q33: =IF(AND(OR(AND(G33-H33>0,L33-N33>0),AND(G33-H33<0,L33-N33<0),AND(G33-H33=0,L33-N33=0)),L33>-1,N33>-1),1,0) -> 0 | R33: =IF(AND(G33=L33,H33=N33,L33>-1,G33>-1),3,0) -> 0 | S33: =Q33+R33 -> 0
A34: 21 | B34: 44891 | D34: Túnez | G34: 2 | H34: 2 | I34: Australia | L34: =OFICIAL!G29 -> 0 | M34: =OFICIAL!G29 -> 0 | N34: =OFICIAL!H29 -> 0 | O34: =OFICIAL!I29 -> Australia | Q34: =IF(AND(OR(AND(G34-H34>0,L34-N34>0),AND(G34-H34<0,L34-N34<0),AND(G34-H34=0,L34-N34=0)),L34>-1,N34>-1),1,0) -> 1 | R34: =IF(AND(G34=L34,H34=N34,L34>-1,G34>-1),3,0) -> 0 | S34: =Q34+R34 -> 1
A35: 23 | B35: 44891 | D35: Francia | G35: 2 | H35: 1 | I35: Dinamarca | L35: =OFICIAL!G30 -> 0 | M35: =OFICIAL!G30 -> 0 | N35: =OFICIAL!H30 -> 0 | O35: =OFICIAL!I30 -> Dinamarca | Q35: =IF(AND(OR(AND(G35-H35>0,L35-N35>0),AND(G35-H35<0,L35-N35<0),AND(G35-H35=0,L35-N35=0)),L35>-1,N35>-1),1,0) -> 0 | R35: =IF(AND(G35=L35,H35=N35,L35>-1,G35>-1),3,0) -> 0 | S35: =Q35+R35 -> 0
A36: 37 | B36: 44895 | D36: Túnez | G36: 0 | H36: 3 | I36: Francia | L36: =OFICIAL!G31 -> 0 | M36: =OFICIAL!G31 -> 0 | N36: =OFICIAL!H31 -> 0 | O36: =OFICIAL!I31 -> Francia | Q36: =IF(AND(OR(AND(G36-H36>0,L36-N36>0),AND(G36-H36<0,L36-N36<0),AND(G36-H36=0,L36-N36=0)),L36>-1,N36>-1),1,0) -> 0 | R36: =IF(AND(G36=L36,H36=N36,L36>-1,G36>-1),3,0) -> 0 | S36: =Q36+R36 -> 0
A37: 38 | B37: 44895 | D37: Australia | G37: 1 | H37: 3 | I37: Dinamarca | L37: =OFICIAL!G32 -> 0 | M37: =OFICIAL!G32 -> 0 | N37: =OFICIAL!H32 -> 0 | O37: =OFICIAL!I32 -> Dinamarca | Q37: =IF(AND(OR(AND(G37-H37>0,L37-N37>0),AND(G37-H37<0,L37-N37<0),AND(G37-H37=0,L37-N37=0)),L37>-1,N37>-1),1,0) -> 0 | R37: =IF(AND(G37=L37,H37=N37,L37>-1,G37>-1),3,0) -> 0 | S37: =Q37+R37 -> 0
A38: Grupo E
A39: 10 | B39: 44888 | D39: Alemania | G39: 2 | H39: 0 | I39: Japón | L39: =OFICIAL!G34 -> 0 | M39: =OFICIAL!G34 -> 0 | N39: =OFICIAL!H34 -> 0 | O39: =OFICIAL!I34 -> Japón | Q39: =IF(AND(OR(AND(G39-H39>0,L39-N39>0),AND(G39-H39<0,L39-N39<0),AND(G39-H39=0,L39-N39=0)),L39>-1,N39>-1),1,0) -> 0 | R39: =IF(AND(G39=L39,H39=N39,L39>-1,G39>-1),3,0) -> 0 | S39: =Q39+R39 -> 0
A40: 11 | B40: 44888 | D40: España | G40: 2 | H40: 0 | I40: Costa Rica | L40: =OFICIAL!G35 -> 0 | M40: =OFICIAL!G35 -> 0 | N40: =OFICIAL!H35 -> 0 | O40: =OFICIAL!I35 -> Costa Rica | Q40: =IF(AND(OR(AND(G40-H40>0,L40-N40>0),AND(G40-H40<0,L40-N40<0),AND(G40-H40=0,L40-N40=0)),L40>-1,N40>-1),1,0) -> 0 | R40: =IF(AND(G40=L40,H40=N40,L40>-1,G40>-1),3,0) -> 0 | S40: =Q40+R40 -> 0
A41: 25 | B41: 44892 | D41: Japón | G41: 1 | H41: 1 | I41: Costa Rica | L41: =OFICIAL!G36 -> 0 | M41: =OFICIAL!G36 -> 0 | N41: =OFICIAL!H36 -> 0 | O41: =OFICIAL!I36 -> Costa Rica | Q41: =IF(AND(OR(AND(G41-H41>0,L41-N41>0),AND(G41-H41<0,L41-N41<0),AND(G41-H41=0,L41-N41=0)),L41>-1,N41>-1),1,0) -> 1 | R41: =IF(AND(G41=L41,H41=N41,L41>-1,G41>-1),3,0) -> 0 | S41: =Q41+R41 -> 1
A42: 28 | B42: 44892 | D42: España | G42: 1 | H42: 2 | I42: Alemania | L42: =OFICIAL!G37 -> 0 | M42: =OFICIAL!G37 -> 0 | N42: =OFICIAL!H37 -> 0 | O42: =OFICIAL!I37 -> Alemania | Q42: =IF(AND(OR(AND(G42-H42>0,L42-N42>0),AND(G42-H42<0,L42-N42<0),AND(G42-H42=0,L42-N42=0)),L42>-1,N42>-1),1,0) -> 0 | R42: =IF(AND(G42=L42,H42=N42,L42>-1,G42>-1),3,0) -> 0 | S42: =Q42+R42 -> 0
...

Sheet AHG
B1: MUNDIAL DE FÚTBOL QATAR 2022 | O1: Premios | Q1: 1 Puesto | S1: 0.7
B2: Escribir solo en las cajas | E2: VERDES | L2: 5 | M2: E | Q2: 2 Puesto | S2: 0.2
B3: No toque ni re formatee nada | Q3: 3 Puesto | S3: 0.1
B5: PARTICIPANTE: | C5: Álvaro Hernández | L5: Resultado: 1 Pt | Q5: No tocar Columnas
L6: Exacto: 4 Pts | Q6: Naranjas
A8: Partido | B8: Fecha | G8: Resultado | L8: Resultado | Q8: Pts
G9: Suyo | L9: Real | Q9: Resu | R9: Exac | S9: Total
A10: Grupo A
A11: 1 | B11: 44885 | D11: Qatar | G11: 0 | H11: 0 | I11: Ecuador | L11: =[1]OFICIAL!G6 -> 0 | M11: =[1]OFICIAL!G6 -> 0 | N11: =[1]OFICIAL!H6 -> 0 | O11: =[1]OFICIAL!I6 -> Ecuador | Q11: =IF(AND(OR(AND(G11-H11>0,L11-N11>0),AND(G11-H11<0,L11-N11<0),AND(G11-H11=0,L11-N11=0)),L11>-1,N11>-1),1,0) -> 1 | R11: =IF(AND(G11=L11,H11=N11,L11>-1,G11>-1),3,0) -> 3 | S11: =Q11+R11 -> 4
A12: 3 | B12: 44886 | D12: Senegal | G12: 2 | H12: 2 | I12: Países Bajos | L12: =[1]OFICIAL!G7 -> 0 | M12: =[1]OFICIAL!G7 -> 0 | N12: =[1]OFICIAL!H7 -> 0 | O12: =[1]OFICIAL!I7 -> Países Bajos | Q12: =IF(AND(OR(AND(G12-H12>0,L12-N12>0),AND(G12-H12<0,L12-N12<0),AND(G12-H12=0,L12-N12=0)),L12>-1,N12>-1),1,0) -> 1 | R12: =IF(AND(G12=L12,H12=N12,L12>-1,G12>-1),3,0) -> 0 | S12: =Q12+R12 -> 1
A13: 18 | B13: 44890 | D13: Qatar | G13: 1 | H13: 2 | I13: Senegal | L13: =[1]OFICIAL!G8 -> 0 | M13: =[1]OFICIAL!G8 -> 0 | N13: =[1]OFICIAL!H8 -> 0 | O13: =[1]OFICIAL!I8 -> Senegal | Q13: =IF(AND(OR(AND(G13-H13>0,L13-N13>0),AND(G13-H13<0,L13-N13<0),AND(G13-H13=0,L13-N13=0)),L13>-1,N13>-1),1,0) -> 0 | R13: =IF(AND(G13=L13,H13=N13,L13>-1,G13>-1),3,0) -> 0 | S13: =Q13+R13 -> 0
A14: 19 | B14: 44890 | D14: Países Bajos | G14: 1 | H14: 0 | I14: Ecuador | L14: =[1]OFICIAL!G9 -> 0 | M14: =[1]OFICIAL!G9 -> 0 | N14: =[1]OFICIAL!H9 -> 0 | O14: =[1]OFICIAL!I9 -> Ecuador | Q14: =IF(AND(OR(AND(G14-H14>0,L14-N14>0),AND(G14-H14<0,L14-N14<0),AND(G14-H14=0,L14-N14=0)),L14>-1,N14>-1),1,0) -> 0 | R14: =IF(AND(G14=L14,H14=N14,L14>-1,G14>-1),3,0) -> 0 | S14: =Q14+R14 -> 0
A15: 33 | B15: 44894 | D15: Países Bajos | G15: 2 | H15: 0 | I15: Qatar | L15: =[1]OFICIAL!G10 -> 0 | M15: =[1]OFICIAL!G10 -> 0 | N15: =[1]OFICIAL!H10 -> 0 | O15: =[1]OFICIAL!I10 -> Qatar | Q15: =IF(AND(OR(AND(G15-H15>0,L15-N15>0),AND(G15-H15<0,L15-N15<0),AND(G15-H15=0,L15-N15=0)),L15>-1,N15>-1),1,0) -> 0 | R15: =IF(AND(G15=L15,H15=N15,L15>-1,G15>-1),3,0) -> 0 | S15: =Q15+R15 -> 0
A16: 34 | B16: 44894 | D16: Ecuador | G16: 1 | H16: 1 | I16: Senegal | L16: =[1]OFICIAL!G11 -> 0 | M16: =[1]OFICIAL!G11 -> 0 | N16: =[1]OFICIAL!H11 -> 0 | O16: =[1]OFICIAL!I11 -> Senegal | Q16: =IF(AND(OR(AND(G16-H16>0,L16-N16>0),AND(G16-H16<0,L16-N16<0),AND(G16-H16=0,L16-N16=0)),L16>-1,N16>-1),1,0) -> 1 | R16: =IF(AND(G16=L16,H16=N16,L16>-1,G16>-1),3,0) -> 0 | S16: =Q16+R16 -> 1
A17: Grupo B
A18: 2 | B18: 44886 | D18: Inglaterra | G18: 1 | H18: 0 | I18: Irán | L18: =[1]OFICIAL!G13 -> 0 | M18: =[1]OFICIAL!G13 -> 0 | N18: =[1]OFICIAL!H13 -> 0 | O18: =[1]OFICIAL!I13 -> Irán | Q18: =IF(AND(OR(AND(G18-H18>0,L18-N18>0),AND(G18-H18<0,L18-N18<0),AND(G18-H18=0,L18-N18=0)),L18>-1,N18>-1),1,0) -> 0 | R18: =IF(AND(G18=L18,H18=N18,L18>-1,G18>-1),3,0) -> 0 | S18: =Q18+R18 -> 0
A19: 4 | B19: 44886 | D19: USA | G19: 2 | H19: 0 | I19: Gales | L19: =[1]OFICIAL!G14 -> 0 | M19: =[1]OFICIAL!G14 -> 0 | N19: =[1]OFICIAL!H14 -> 0 | O19: =[1]OFICIAL!I14 -> Gales | Q19: =IF(AND(OR(AND(G19-H19>0,L19-N19>0),AND(G19-H19<0,L19-N19<0),AND(G19-H19=0,L19-N19=0)),L19>-1,N19>-1),1,0) -> 0 | R19: =IF(AND(G19=L19,H19=N19,L19>-1,G19>-1),3,0) -> 0 | S19: =Q19+R19 -> 0
A20: 17 | B20: 44890 | D20: Gales | G20: 0 | H20: 1 | I20: Irán | L20: =[1]OFICIAL!G15 -> 0 | M20: =[1]OFICIAL!G15 -> 0 | N20: =[1]OFICIAL!H15 -> 0 | O20: =[1]OFICIAL!I15 -> Irán | Q20: =IF(AND(OR(AND(G20-H20>0,L20-N20>0),AND(G20-H20<0,L20-N20<0),AND(G20-H20=0,L20-N20=0)),L20>-1,N20>-1),1,0) -> 0 | R20: =IF(AND(G20=L20,H20=N20,L20>-1,G20>-1),3,0) -> 0 | S20: =Q20+R20 -> 0
A21: 20 | B21: 44890 | D21: Inglaterra | G21: 2 | H21: 2 | I21: USA | L21: =[1]OFICIAL!G16 -> 0 | M21: =[1]OFICIAL!G16 -> 0 | N21: =[1]OFICIAL!H16 -> 0 | O21: =[1]OFICIAL!I16 -> USA | Q21: =IF(AND(OR(AND(G21-H21>0,L21-N21>0),AND(G21-H21<0,L21-N21<0),AND(G21-H21=0,L21-N21=0)),L21>-1,N21>-1),1,0) -> 1 | R21: =IF(AND(G21=L21,H21=N21,L21>-1,G21>-1),3,0) -> 0 | S21: =Q21+R21 -> 1
A22: 35 | B22: 44894 | D22: Gales | G22: 1 | H22: 3 | I22: Inglaterra | L22: =[1]OFICIAL!G17 -> 0 | M22: =[1]OFICIAL!G17 -> 0 | N22: =[1]OFICIAL!H17 -> 0 | O22: =[1]OFICIAL!I17 -> Inglaterra | Q22: =IF(AND(OR(AND(G22-H22>0,L22-N22>0),AND(G22-H22<0,L22-N22<0),AND(G22-H22=0,L22-N22=0)),L22>-1,N22>-1),1,0) -> 0 | R22: =IF(AND(G22=L22,H22=N22,L22>-1,G22>-1),3,0) -> 0 | S22: =Q22+R22 -> 0
A23: 36 | B23: 44894 | D23: Irán | G23: 1 | H23: 2 | I23: USA | L23: =[1]OFICIAL!G18 -> 0 | M23: =[1]OFICIAL!G18 -> 0 | N23: =[1]OFICIAL!H18 -> 0 | O23: =[1]OFICIAL!I18 -> USA | Q23: =IF(AND(OR(AND(G23-H23>0,L23-N23>0),AND(G23-H23<0,L23-N23<0),AND(G23-H23=0,L23-N23=0)),L23>-1,N23>-1),1,0) -> 0 | R23: =IF(AND(G23=L23,H23=N23,L23>-1,G23>-1),3,0) -> 0 | S23: =Q23+R23 -> 0
A24: Grupo C
A25: 5 | B25: 44887 | D25: Argentina | G25: 3 | H25: 0 | I25: Arabia Saudí | L25: =[1]OFICIAL!G20 -> 0 | M25: =[1]OFICIAL!G20 -> 0 | N25: =[1]OFICIAL!H20 -> 0 | O25: =[1]OFICIAL!I20 -> Arabia Saudí | Q25: =IF(AND(OR(AND(G25-H25>0,L25-N25>0),AND(G25-H25<0,L25-N25<0),AND(G25-H25=0,L25-N25=0)),L25>-1,N25>-1),1,0) -> 0 | R25: =IF(AND(G25=L25,H25=N25,L25>-1,G25>-1),3,0) -> 0 | S25: =Q25+R25 -> 0
A26: 7 | B26: 44887 | D26: México | G26: 2 | H26: 1 | I26: Polonia | L26: =[1]OFICIAL!G21 -> 0 | M26: =[1]OFICIAL!G21 -> 0 | N26: =[1]OFICIAL!H21 -> 0 | O26: =[1]OFICIAL!I21 -> Polonia | Q26: =IF(AND(OR(AND(G26-H26>0,L26-N26>0),AND(G26-H26<0,L26-N26<0),AND(G26-H26=0,L26-N26=0)),L26>-1,N26>-1),1,0) -> 0 | R26: =IF(AND(G26=L26,H26=N26,L26>-1,G26>-1),3,0) -> 0 | S26: =Q26+R26 -> 0
A27: 22 | B27: 44891 | D27: Polonia | G27: 2 | H27: 0 | I27: Arabia Saudí | L27: =[1]OFICIAL!G22 -> 0 | M27: =[1]OFICIAL!G22 -> 0 | N27: =[1]OFICIAL!H22 -> 0 | O27: =[1]OFICIAL!I22 -> Arabia Saudí | Q27: =IF(AND(OR(AND(G27-H27>0,L27-N27>0),AND(G27-H27<0,L27-N27<0),AND(G27-H27=0,L27-N27=0)),L27>-1,N27>-1),1,0) -> 0 | R27: =IF(AND(G27=L27,H27=N27,L27>-1,G27>-1),3,0) -> 0 | S27: =Q27+R27 -> 0
A28: 24 | B28: 44891 | D28: Argentina | G28: 2 | H28: 1 | I28: México | L28: =[1]OFICIAL!G23 -> 0 | M28: =[1]OFICIAL!G23 -> 0 | N28: =[1]OFICIAL!H23 -> 0 | O28: =[1]OFICIAL!I23 -> México | Q28: =IF(AND(OR(AND(G28-H28>0,L28-N28>0),AND(G28-H28<0,L28-N28<0),AND(G28-H28=0,L28-N28=0)),L28>-1,N28>-1),1,0) -> 0 | R28: =IF(AND(G28=L28,H28=N28,L28>-1,G28>-1),3,0) -> 0 | S28: =Q28+R28 -> 0
A29: 39 | B29: 44895 | D29: Arabia Saudí | G29: 0 | H29: 2 | I29: México | L29: =[1]OFICIAL!G24 -> 0 | M29: =[1]OFICIAL!G24 -> 0 | N29: =[1]OFICIAL!H24 -> 0 | O29: =[1]OFICIAL!I24 -> México | Q29: =IF(AND(OR(AND(G29-H29>0,L29-N29>0),AND(G29-H29<0,L29-N29<0),AND(G29-H29=0,L29-N29=0)),L29>-1,N29>-1),1,0) -> 0 | R29: =IF(AND(G29=L29,H29=N29,L29>-1,G29>-1),3,0) -> 0 | S29: =Q29+R29 -> 0
A30: 40 | B30: 44895 | D30: Polonia | G30: 0 | H30: 2 | I30: Argentina | L30: =[1]OFICIAL!G25 -> 0 | M30: =[1]OFICIAL!G25 -> 0 | N30: =[1]OFICIAL!H25 -> 0 | O30: =[1]OFICIAL!I25 -> Argentina | Q30: =IF(AND(OR(AND(G30-H30>0,L30-N30>0),AND(G30-H30<0,L30-N30<0),AND(G30-H30=0,L30-N30=0)),L30>-1,N30>-1),1,0) -> 0 | R30: =IF(AND(G30=L30,H30=N30,L30>-1,G30>-1),3,0) -> 0 | S30: =Q30+R30 -> 0
A31: Grupo D
A32: 6 | B32: 44887 | D32: Dinamarca | G32: 2 | H32: 0 | I32: Túnez | L32: =[1]OFICIAL!G27 -> 0 | M32: =[1]OFICIAL!G27 -> 0 | N32: =[1]OFICIAL!H27 -> 0 | O32: =[1]OFICIAL!I27 -> Túnez | Q32: =IF(AND(OR(AND(G32-H32>0,L32-N32>0),AND(G32-H32<0,L32-N32<0),AND(G32-H32=0,L32-N32=0)),L32>-1,N32>-1),1,0) -> 0 | R32: =IF(AND(G32=L32,H32=N32,L32>-1,G32>-1),3,0) -> 0 | S32: =Q32+R32 -> 0
A33: 8 | B33: 44887 | D33: Francia | G33: 3 | H33: 1 | I33: Australia | L33: =[1]OFICIAL!G28 -> 0 | M33: =[1]OFICIAL!G28 -> 0 | N33: =[1]OFICIAL!H28 -> 0 | O33: =[1]OFICIAL!I28 -> Australia | Q33: =IF(AND(OR(AND(G33-H33>0,L33-N33>0),AND(G33-H33<0,L33-N33<0),AND(G33-H33=0,L33-N33=0)),L33>-1,N33>-1),1,0) -> 0 | R33: =IF(AND(G33=L33,H33=N33,L33>-1,G33>-1),3,0) -> 0 | S33: =Q33+R33 -> 0
A34: 21 | B34: 44891 | D34: Túnez | G34: 1 | H34: 1 | I34: Australia | L34: =[1]OFICIAL!G29 -> 0 | M34: =[1]OFICIAL!G29 -> 0 | N34: =[1]OFICIAL!H29 -> 0 | O34: =[1]OFICIAL!I29 -> Australia | Q34: =IF(AND(OR(AND(G34-H34>0,L34-N34>0),AND(G34-H34<0,L34-N34<0),AND(G34-H34=0,L34-N34=0)),L34>-1,N34>-1),1,0) -> 1 | R34: =IF(AND(G34=L34,H34=N34,L34>-1,G34>-1),3,0) -> 0 | S34: =Q34+R34 -> 1
A35: 23 | B35: 44891 | D35: Francia | G35: 2 | H35: 0 | I35: Dinamarca | L35: =[1]OFICIAL!G30 -> 0 | M35: =[1]OFICIAL!G30 -> 0 | N35: =[1]OFICIAL!H30 -> 0 | O35: =[1]OFICIAL!I30 -> Dinamarca | Q35: =IF(AND(OR(AND(G35-H35>0,L35-N35>0),AND(G35-H35<0,L35-N35<0),AND(G35-H35=0,L35-N35=0)),L35>-1,N35>-1),1,0) -> 0 | R35: =IF(AND(G35=L35,H35=N35,L35>-1,G35>-1),3,0) -> 0 | S35: =Q35+R35 -> 0
A36: 37 | B36: 44895 | D36: Túnez | G36: 2 | H36: 2 | I36: Francia | L36: =[1]OFICIAL!G31 -> 0 | M36: =[1]OFICIAL!G31 -> 0 | N36: =[1]OFICIAL!H31 -> 0 | O36: =[1]OFICIAL!I31 -> Francia | Q36: =IF(AND(OR(AND(G36-H36>0,L36-N36>0),AND(G36-H36<0,L36-N36<0),AND(G36-H36=0,L36-N36=0)),L36>-1,N36>-1),1,0) -> 1 | R36: =IF(AND(G36=L36,H36=N36,L36>-1,G36>-1),3,0) -> 0 | S36: =Q36+R36 -> 1
A37: 38 | B37: 44895 | D37: Australia | G37: 0 | H37: 2 | I37: Dinamarca | L37: =[1]OFICIAL!G32 -> 0 | M37: =[1]OFICIAL!G32 -> 0 | N37: =[1]OFICIAL!H32 -> 0 | O37: =[1]OFICIAL!I32 -> Dinamarca | Q37: =IF(AND(OR(AND(G37-H37>0,L37-N37>0),AND(G37-H37<0,L37-N37<0),AND(G37-H37=0,L37-N37=0)),L37>-1,N37>-1),1,0) -> 0 | R37: =IF(AND(G37=L37,H37=N37,L37>-1,G37>-1),3,0) -> 0 | S37: =Q37+R37 -> 0
A38: Grupo E
A39: 10 | B39: 44888 | D39: Alemania | G39: 1 | H39: 0 | I39: Japón | L39: =[1]OFICIAL!G34 -> 0 | M39: =[1]OFICIAL!G34 -> 0 | N39: =[1]OFICIAL!H34 -> 0 | O39: =[1]OFICIAL!I34 -> Japón | Q39: =IF(AND(OR(AND(G39-H39>0,L39-N39>0),AND(G39-H39<0,L39-N39<0),AND(G39-H39=0,L39-N39=0)),L39>-1,N39>-1),1,0) -> 0 | R39: =IF(AND(G39=L39,H39=N39,L39>-1,G39>-1),3,0) -> 0 | S39: =Q39+R39 -> 0
A40: 11 | B40: 44888 | D40: España | G40: 1 | H40: 0 | I40: Costa Rica | L40: =[1]OFICIAL!G35 -> 0 | M40: =[1]OFICIAL!G35 -> 0 | N40: =[1]OFICIAL!H35 -> 0 | O40: =[1]OFICIAL!I35 -> Costa Rica | Q40: =IF(AND(OR(AND(G40-H40>0,L40-N40>0),AND(G40-H40<0,L40-N40<0),AND(G40-H40=0,L40-N40=0)),L40>-1,N40>-1),1,0) -> 0 | R40: =IF(AND(G40=L40,H40=N40,L40>-1,G40>-1),3,0) -> 0 | S40: =Q40+R40 -> 0
A41: 25 | B41: 44892 | D41: Japón | G41: 1 | H41: 1 | I41: Costa Rica | L41: =[1]OFICIAL!G36 -> 0 | M41: =[1]OFICIAL!G36 -> 0 | N41: =[1]OFICIAL!H36 -> 0 | O41: =[1]OFICIAL!I36 -> Costa Rica | Q41: =IF(AND(OR(AND(G41-H41>0,L41-N41>0),AND(G41-H41<0,L41-N41<0),AND(G41-H41=0,L41-N41=0)),L41>-1,N41>-1),1,0) -> 1 | R41: =IF(AND(G41=L41,H41=N41,L41>-1,G41>-1),3,0) -> 0 | S41: =Q41+R41 -> 1
A42: 28 | B42: 44892 | D42: España | G42: 0 | H42: 2 | I42: Alemania | L42: =[1]OFICIAL!G37 -> 0 | M42: =[1]OFICIAL!G37 -> 0 | N42: =[1]OFICIAL!H37 -> 0 | O42: =[1]OFICIAL!I37 -> Alemania | Q42: =IF(AND(OR(AND(G42-H42>0,L42-N42>0),AND(G42-H42<0,L42-N42<0),AND(G42-H42=0,L42-N42=0)),L42>-1,N42>-1),1,0) -> 0 | R42: =IF(AND(G42=L42,H42=N42,L42>-1,G42>-1),3,0) -> 0 | S42: =Q42+R42 -> 0
...

Sheet CSE
B1: MUNDIAL DE FÚTBOL QATAR 2022 | O1: Premios | Q1: 1 Puesto | S1: 0.7
B2: Escribir solo en las cajas | E2: VERDES | L2: 5 | M2: E | Q2: 2 Puesto | S2: 0.2
B3: No toque ni re formatee nada | Q3: 3 Puesto | S3: 0.1
B5: PARTICIPANTE: | C5: Esther Cortés Suris | L5: Resultado: 1 Pt | Q5: No tocar Columnas
L6: Exacto: 4 Pts | Q6: Naranjas
A8: Partido | B8: Fecha | G8: Resultado | L8: Resultado | Q8: Pts
G9: Suyo | L9: Real | Q9: Resu | R9: Exac | S9: Total
A10: Grupo A
A11: 1 | B11: 44885 | D11: Qatar | G11: 1 | H11: 2 | I11: Ecuador | L11: =OFICIAL!G6 -> 0 | M11: =OFICIAL!G6 -> 0 | N11: =OFICIAL!H6 -> 2 | O11: =OFICIAL!I6 -> Ecuador | Q11: =IF(AND(OR(AND(G11-H11>0,L11-N11>0),AND(G11-H11<0,L11-N11<0),AND(G11-H11=0,L11-N11=0)),L11>-1,N11>-1),1,0) -> 1 | R11: =IF(AND(G11=L11,H11=N11,L11>-1,G11>-1),3,0) -> 0 | S11: =Q11+R11 -> 1
A12: 3 | B12: 44886 | D12: Senegal | G12: 2 | H12: 2 | I12: Países Bajos | L12: =OFICIAL!G7 -> 0 | M12: =OFICIAL!G7 -> 0 | N12: =OFICIAL!H7 -> 0 | O12: =OFICIAL!I7 -> Países Bajos | Q12: =IF(AND(OR(AND(G12-H12>0,L12-N12>0),AND(G12-H12<0,L12-N12<0),AND(G12-H12=0,L12-N12=0)),L12>-1,N12>-1),1,0) -> 1 | R12: =IF(AND(G12=L12,H12=N12,L12>-1,G12>-1),3,0) -> 0 | S12: =Q12+R12 -> 1
A13: 18 | B13: 44890 | D13: Qatar | G13: 0 | H13: 1 | I13: Senegal | L13: =OFICIAL!G8 -> 0 | M13: =OFICIAL!G8 -> 0 | N13: =OFICIAL!H8 -> 0 | O13: =OFICIAL!I8 -> Senegal | Q13: =IF(AND(OR(AND(G13-H13>0,L13-N13>0),AND(G13-H13<0,L13-N13<0),AND(G13-H13=0,L13-N13=0)),L13>-1,N13>-1),1,0) -> 0 | R13: =IF(AND(G13=L13,H13=N13,L13>-1,G13>-1),3,0) -> 0 | S13: =Q13+R13 -> 0
A14: 19 | B14: 44890 | D14: Países Bajos | G14: 2 | H14: 1 | I14: Ecuador | L14: =OFICIAL!G9 -> 0 | M14: =OFICIAL!G9 -> 0 | N14: =OFICIAL!H9 -> 0 | O14: =OFICIAL!I9 -> Ecuador | Q14: =IF(AND(OR(AND(G14-H14>0,L14-N14>0),AND(G14-H14<0,L14-N14<0),AND(G14-H14=0,L14-N14=0)),L14>-1,N14>-1),1,0) -> 0 | R14: =IF(AND(G14=L14,H14=N14,L14>-1,G14>-1),3,0) -> 0 | S14: =Q14+R14 -> 0
A15: 33 | B15: 44894 | D15: Países Bajos | G15: 3 | H15: 0 | I15: Qatar | L15: =OFICIAL!G10 -> 0 | M15: =OFICIAL!G10 -> 0 | N15: =OFICIAL!H10 -> 0 | O15: =OFICIAL!I10 -> Qatar | Q15: =IF(AND(OR(AND(G15-H15>0,L15-N15>0),AND(G15-H15<0,L15-N15<0),AND(G15-H15=0,L15-N15=0)),L15>-1,N15>-1),1,0) -> 0 | R15: =IF(AND(G15=L15,H15=N15,L15>-1,G15>-1),3,0) -> 0 | S15: =Q15+R15 -> 0
A16: 34 | B16: 44894 | D16: Ecuador | G16: 1 | H16: 1 | I16: Senegal | L16: =OFICIAL!G11 -> 0 | M16: =OFICIAL!G11 -> 0 | N16: =OFICIAL!H11 -> 0 | O16: =OFICIAL!I11 -> Senegal | Q16: =IF(AND(OR(AND(G16-H16>0,L16-N16>0),AND(G16-H16<0,L16-N16<0),AND(G16-H16=0,L16-N16=0)),L16>-1,N16>-1),1,0) -> 1 | R16: =IF(AND(G16=L16,H16=N16,L16>-1,G16>-1),3,0) -> 0 | S16: =Q16+R16 -> 1
A17: Grupo B
A18: 2 | B18: 44886 | D18: Inglaterra | G18: 2 | H18: 0 | I18: Irán | L18: =OFICIAL!G13 -> 0 | M18: =OFICIAL!G13 -> 0 | N18: =OFICIAL!H13 -> 0 | O18: =OFICIAL!I13 -> Irán | Q18: =IF(AND(OR(AND(G18-H18>0,L18-N18>0),AND(G18-H18<0,L18-N18<0),AND(G18-H18=0,L18-N18=0)),L18>-1,N18>-1),1,0) -> 0 | R18: =IF(AND(G18=L18,H18=N18,L18>-1,G18>-1),3,0) -> 0 | S18: =Q18+R18 -> 0
